Workbook

Sheet Skills Matrix
A1: QUANTITATIVE FINANCE SKILLS MATRIX
A2: Technical Competencies Demonstrated in Portfolio Analytics Platform
A4: # | B4: Skill / Competency | C4: Category | D4: CFA Alignment | E4: Implementation | F4: Sheet Reference
A5: 1 | B5: Transaction Ledger with Data Validation | C5: Data Management | D5: Level I — Quant Methods | E5: Structured tables, drop-down controls, non-negative constraints | F5: Ledger
A6: 2 | B6: Tax-Aware Holding Period Tracking | C6: Tax Management | D6: Level I — Tax & Estate | E6: MAXIFS for lot matching, ST/LT gain classification per IRS §1222 | F6: Ledger I:J
A7: 3 | B7: Linked Data Type Integration | C7: Data Engineering | D7: Level I — Equity Investments | E7: Excel Stock entities, .Price, .Beta, .Industry dot-notation | F7: Ledger, Dashboard
A8: 4 | B8: Dynamic Array Portfolio Construction | C8: Portfolio Mgmt | D8: Level III — Portfolio Mgmt | E8: SORT(UNIQUE()) with INDEX/MATCH entity resolution | F8: Dashboard B7
A9: 5 | B9: Market-Cap Weighted Returns | C9: Performance | D9: Level I — Portfolio Mgmt | E9: SUMIF/SUMPRODUCT for weighted aggregation | F9: Dashboard F7:I22
A10: 6 | B10: CAPM Implementation | C10: Asset Pricing | D10: Level I — Corporate Finance | E10: Rf + β(Rm−Rf) with live beta from linked data types | F10: Risk Analytics
A11: 7 | B11: Jensen's Alpha (α) | C11: Performance Attr | D11: Level II — Equity Valuation | E11: α = Rp − [Rf + β(Rm−Rf)], portfolio-level excess return | F11: Risk Analytics C11
A12: 8 | B12: Sharpe Ratio | C12: Risk-Adjusted Perf | D12: Level I — Portfolio Mgmt | E12: (Rp−Rf)/σp — excess return per unit total risk | F12: Risk Analytics C18
A13: 9 | B13: Sortino Ratio | C13: Risk-Adjusted Perf | D13: Level II — Portfolio Mgmt | E13: (Rp−Rf)/Downside σ — penalises harmful volatility only | F13: Risk Analytics C19
A14: 10 | B14: Treynor Ratio | C14: Risk-Adjusted Perf | D14: Level II — Portfolio Mgmt | E14: (Rp−Rf)/β — excess return per unit systematic risk | F14: Risk Analytics C15
A15: 11 | B15: Information Ratio | C15: Active Mgmt | D15: Level III — Performance Eval | E15: α / Tracking Error — active return per unit active risk | F15: Risk Analytics C16
A16: 12 | B16: Calmar Ratio | C16: Hedge Fund Metrics | D16: Level III — Alternatives | E16: CAGR / |Max Drawdown| — return per unit worst-case loss | F16: Risk Analytics C20
... A34: 30 | B34: Cross-Sheet Validation Framework | C34: Model Integrity | D34: CFA Ethics — Diligence | E34: 23 automated consistency checks, tolerance-based assertions | F34: Validation
A36: PROFICIENCY SUMMARY
A37: Category | B37: Count | C37: CFA Level | D37: Depth
A38: Risk Management | B38: 6 | C38: Level II–III | D38: Advanced
A39: Risk-Adjusted Performance | B39: 5 | C39: Level I–III | D39: Comprehensive
A40: Portfolio Management | B40: 5 | C40: Level I–III | D40: Advanced
A41: Active Management | B41: 2 | C41: Level III | D41: Institutional
A42: Data Engineering | B42: 3 | C42: Level I | D42: Applied
A43: Asset Pricing & Attribution | B43: 3 | C43: Level I–II | D43: Core
A44: Factor Investing & Optimization | B44: 3 | C44: Level II–III | D44: Graduate
A45: Model Integrity & Validation | B45: 3 | C45: Level I–Ethics | D45: Professional
A47: VBA MACRO CODE (Copy to VBA Editor: Alt+F11 → Insert Module)
A48: Sub RefreshAllData() Application.CalculateFull Dim ws As Worksheet For Each ws In ThisWorkbook.Worksheets ws.UsedRange.Calculate Next ws MsgBox "All data refreshed.", vbInformation End Sub
A50: Sub ExportDashboardPDF() Dim ws As Worksheet: Set ws = Sheets("Dashboard") Dim fPath As String fPath = Application.GetSaveAsFilename("Portfolio_Dashboard", "PDF Files (*.pdf),*.pdf") If fPath <> "False" Then ws.ExportAsFixedFormat xlTypePDF, fPath, xlQualityStandard MsgBox "Dashboard exported to: " & fPath, vbInformation End If End Sub

Sheet README
A1: 📊 STOCK PORTFOLIO TRACKER & QUANTITATIVE ANALYTICS ENGINE
A2: An institutional-grade Excel-based portfolio analytics platform featuring CAPM, Black-Litterman optimization, Cornish-Fisher VaR, and multi-factor risk decomposition
A4: 🎯 PROJECT OVERVIEW
A5: Objective | B5: Build a production-quality stock portfolio analytics system demonstrating mastery of quantitative finance, risk management, and portfolio optimization - spanning CFA Level I–III curriculum concepts including CAPM, Black-Litterman, Cornish-Fisher VaR, multi-factor attribution, and tax-aware rebalancing.
A6: Scope | B6: 16 stocks across 10 GICS industries, tracked over 7 years (2019–2025) with 112 Buy/Sell transactions. Live market data via Excel Linked Data Types, automated P&L, risk decomposition, stress testing, and Bayesian portfolio optimization.
A7: Investment Strategy | B7: Long-only equity portfolio with systematic $10K annual allocation. 35% Technology, 20% Financials, 45% diversified sectors. Volatility-scaled rebalancing bands replace static thresholds. Tax-aware lot matching per IRS §1222.
A8: Data Sources | B8: Excel Linked Data Types (Stocks) for live prices, beta, industry, P/E. STOCKHISTORY for 12-month sparklines. CFA curriculum-aligned risk-free rate (US 10Y Treasury 4.25%), equity risk premium (5.75%), and market volatility (σm ≈ 15.5%).
A10: WORKBOOK STRUCTURE
A11: Sheet Name | B11: Description
A12: Dashboard | B12: Primary portfolio dashboard with dual-row KPI strip (Portfolio Value, CAGR, Sharpe, Sortino, Alpha, M², Treynor, Calmar, CF VaR), live prices via Linked Data Types, 16-stock analytics table, sector allocation, volatility-scaled rebalancing with tax flags, 3 embedded charts, and auto-refreshing narrative insight summary.
A13: Analytics | B13: Deeper per-stock analytics: individual CAGR, return attribution, cost basis breakdown, risk scores, and annualized return metrics. Mirrors Dashboard data with extended detail.
A14: Ledger | B14: Transaction ledger: 112 records, 16 stocks, 7 years. Includes Holding Period (MAXIFS lot matching) and Tax Status (LT/ST classification per IRS §1222). Data validation on Price (≥0), Units (≥0), and Transaction Type (Buy/Sell dropdown).
A15: Watchlist | B15: Competitor analysis: 10 rival stocks with live data, 52-week ranges, beta, P/E, market cap.
A16: Risk Analytics | B16: Comprehensive risk analytics: CAPM (Rf, Rm, ERP, βp), 6 performance ratios (Sharpe, Sortino, Treynor, IR, Calmar, M²), Parametric VaR (95%/99%), Cornish-Fisher VaR (skew/kurtosis-adjusted), Historical VaR, Expected Shortfall (CVaR), Drawdown Analysis (Max DD, Ulcer Index), Stress Testing (VIX, Tech, Rates), 16-stock risk decomposition with data-bar heatmaps, Fama-French style factors, and Capital Market Line positioning.
A17: WL Dashboard | B17: Watchlist scoring model: multi-factor evaluation (P/E, Beta, 52-week range, margin of safety) with composite rankings and entry-point signals.
A18: Validation | B18: Automated CFA-grade integrity tests: weight summation, P&L identity, HHI consistency, CAPM internal consistency, cross-sheet beta/Sharpe/Treynor reconciliation. 23 tests with real-time pass/fail status.
A19: Optimization | B19: Black-Litterman portfolio optimization: Bayesian framework combining market equilibrium priors (δ=2.5, τ=0.05) with investor views. 16-stock implied equilibrium returns, BL optimal weights, 5-slot view input panel (confidence-weighted), and dollar-denominated trade list with BUY/SELL/HOLD actions.
A20: Skills Matrix | B20: Recruiter-ready competency matrix: 30 quantitative finance skills mapped to CFA Level I–III curriculum, with implementation details and sheet references. 8-category proficiency summary. VBA macro code for data refresh and PDF export.
A21: Sparkline | B21: Price history data feeding Dashboard sparkline trend visualizations.
A22: Stock Sheets | B22: Individual stock deep-dives with STOCKHISTORY price series and charts.
A24: KEY FORMULAS & TECHNIQUES
A25: Technique | B25: Implementation
A26: Dynamic Arrays | B26: SORT, UNIQUE, FILTER, SORTBY with spill ranges for automatic data propagation
A27: Linked Data Types | B27: Excel Stocks data type with dot notation for real-time market data integration
A28: STOCKHISTORY | B28: Historical price series retrieval for sparklines and stock analysis sheets
A29: SUMIF / COUNTIF | B29: Cross-sheet aggregation for transaction totals and sector-level rollups from Ledger
A30: INDEX / MATCH | B30: Best and worst performer identification with dynamic lookups across spill ranges
A31: CAGR Formula | B31: Annualised return: (Ending Value / Beginning Value) ^ (1 / Years) - 1
A32: HHI Index | B32: Sum of squared sector weights to quantify portfolio concentration risk
A33: Conditional Formatting | B33: Automated color coding for negative/positive values with emoji risk indicators
A34: Allocation Model | B34: Weighted allocation with sector caps (Tech max 35%) and systematic Buy/Sell rules
A35: CAPM | B35: E(Ri) = Rf + βi(Rm − Rf). Capital Asset Pricing Model for expected returns. Jensen’s Alpha = Rp − E(Rp). Live betas from Linked Data Types.
A36: Cornish-Fisher VaR | B36: VaR adjusted for skewness (S) and kurtosis (K): z_cf = z + (z²−1)S/6 + (z³−3z)K/24 − (2z³−5z)S²/36. Per Jorion (2007), Maillard (2012).
... A44: Data Bar Heatmaps | B44: Conditional formatting data bars on risk decomposition table: Beta (red scale), Alpha (green/red), CAGR (blue), Weight (yellow for concentration). Visual risk identification.
A46: SKILLS DEMONSTRATED
A47: Category | B47: Skills
A48: Financial Modelling | B48: Portfolio construction, P&L tracking, CAGR analysis, 6 risk-adjusted performance metrics (Sharpe, Sortino, Treynor, IR, Calmar, M²), CAPM implementation, Jensen’s Alpha, Black-Litterman optimization
A49: Data Engineering | B49: Dynamic arrays (SORT, UNIQUE, FILTER), Linked Data Types with dot notation, structured table references, cross-sheet data pipelines, STOCKHISTORY integration, INDEX/MATCH entity resolution
A50: Risk Analysis | B50: CAPM, Parametric VaR (95%/99%), Cornish-Fisher adjusted VaR, Historical VaR, CVaR/Expected Shortfall, drawdown analysis, Ulcer Index, stress testing (3 scenarios), factor decomposition, CML analysis
A51: Dashboard Design | B51: Dual-row KPI strip with 14 metrics, conditional formatting data bars, doughnut/bar/scatter charts, emoji-coded signals, auto-refreshing narrative summary, professional #2D4A7A/#1E3A5F color system
...

Sheet Validation
A1: PORTFOLIO VALIDATION TESTS
A2: Automated integrity checks · Audit framework · Real-time validation
A4: DATA INTEGRITY CHECKS
A5: Test | B5: Expected | C5: Actual | D5: Status | E5: Notes
A6: Portfolio weights sum to 100% | B6: 1 | C6: =SUM(Dashboard!M7:M22) -> 1 | D6: =IF(ABS(C6-1)<0.001,"✅ PASS","❌ FAIL") -> ✅ PASS | E6: Sum of all portfolio weights must equal 100%
A7: Total MV = Sum of holdings MV | B7: =Dashboard!B3 -> 303680.39 | C7: =SUM(Dashboard!G7:G22) -> 303680.39 | D7: =IF(ABS(B7-C7)<1,"✅ PASS","❌ FAIL") -> ✅ PASS | E7: Portfolio value KPI matches sum of individual market values
A8: Cost basis consistency | B8: =Dashboard!E3 -> 132051.42 | C8: =SUM(Dashboard!O7:O22) -> 132051.42 | D8: =IF(ABS(B8-C8)<1,"✅ PASS","❌ FAIL") -> ✅ PASS | E8: Portfolio cost basis KPI matches sum of per-stock cost bases
A9: P&L identity: MV - CB = Unrealised P&L | B9: =Dashboard!F3 -> 171628.96 | C9: =Dashboard!B3-Dashboard!E3 -> 171628.96 | D9: =IF(ABS(B9-C9)<1,"✅ PASS","❌ FAIL") -> ✅ PASS | E9: Accounting identity: Unrealised P&L = Market Value − Cost Basis
A10: Unique stock count matches | B10: 16 | C10: =COUNTA(Dashboard!B7:B22) -> 16 | D10: =IF(B10=C10,"✅ PASS","❌ FAIL") -> ✅ PASS | E10: Dashboard shows all 16 unique stocks from Ledger
A11: Sector allocation weights sum to 100% | B11: 1 | C11: =SUM(Dashboard!E30:E39) -> 1 | D11: =IF(ABS(C11-1)<0.001,"✅ PASS","❌ FAIL") -> ✅ PASS | E11: Sector allocation must sum to 100%
A12: HHI consistency (Dashboard vs Analytics) | B12: =Dashboard!K3 -> 0.18756228 | C12: =Dashboard!L25 -> 0.18756228 | D12: =IF(ABS(B12-C12)<0.001,"✅ PASS","❌ FAIL") -> ✅ PASS | E12: HHI Index must be identical between KPI strip and bottom KPIs
A13: HHI = sum of sector squared weights | B13: =Dashboard!K3 -> 0.18756228 | C13: =SUM(Dashboard!F30:F39) -> 0.18756228 | D13: =IF(ABS(B13-C13)<0.001,"✅ PASS","❌ FAIL") -> ✅ PASS | E13: HHI = Σ(wi²) from sector allocation table
A14: Win rate consistency | B14: =Dashboard!P3 -> 0.875 | C14: =COUNTIF(Dashboard!J7:J22,">0")/COUNTA(Dashboard!J7:J22) -> 0.875 | D14: =IF(ABS(B14-C14)<0.001,"✅ PASS","❌ FAIL") -> ✅ PASS | E14: Win rate KPI matches manual count of profitable holdings
A15: Rebalancing equal weights = 1/N | B15: =1/16 -> 0.0625 | C15: =Dashboard!J30 -> 0.0625 | D15: =IF(ABS(B15-C15)<0.001,"✅ PASS","❌ FAIL") -> ✅ PASS | E15: Equal weight target = 1/N = 6.25% for 16 stocks
A16: Sector MV = sum of stock MVs per sector | B16: =Dashboard!B3 -> 303680.39 | C16: =SUM(Dashboard!D30:D39) -> 303680.39 | D16: =IF(ABS(B16-C16)<1,"✅ PASS","❌ FAIL") -> ✅ PASS | E16: Sum of sector market values equals total portfolio market value
A18: RISK METRIC CHECKS
A19: Test | B19: Expected Range | C19: Actual | D19: Status | E19: CFA Framework
A20: Sharpe Ratio in valid range | B20: -3.0 to 5.0 | C20: =Dashboard!O3 -> 0.46593002 | D20: =IF(AND(C20>=-3,C20<=5),"✅ PASS","⚠️ CHECK") -> ✅ PASS | E20: Sharpe = (Rp−Rf)/σp; typical range -3 to 5 for diversified portfolios
A21: Portfolio Beta reasonable | B21: 0.3 to 2.5 | C21: =Dashboard!S3 -> 1.4726694 | D21: =IF(AND(C21>=0.3,C21<=2.5),"✅ PASS","⚠️ CHECK") -> ✅ PASS | E21: βp = Σ(wi×βi); 0.3-2.5 typical for equity-only portfolio
A22: Treynor Ratio valid | B22: -0.5 to 1.0 | C22: =Dashboard!T3 -> 0.072219153 | D22: =IF(AND(C22>=-0.5,C22<=1),"✅ PASS","⚠️ CHECK") -> ✅ PASS | E22: Treynor = (Rp−Rf)/βp; measures excess return per unit systematic risk
A23: Worst stock return ≤ 0 | B23: ≤ 0% | C23: =Dashboard!R3 -> -0.13381728 | D23: =IF(C23<=0,"✅ PASS","❌ FAIL") -> ✅ PASS | E23: Max drawdown must be negative or zero (worst single-stock return)
A24: Calmar Ratio positive (if CAGR positive) | B24: > 0 | C24: =Dashboard!S25 -> 1.1123746 | D24: =IF(C24>0,"✅ PASS","⚠️ CHECK") -> ✅ PASS | E24: Calmar = CAGR/|Max DD|; positive when portfolio has positive CAGR
A26: SUMMARY
A27: Tests Passed | B27: Tests Failed | C27: Tests Warning | D27: Overall Score
A28: =COUNTIF(D6:D16,"✅*")+COUNTIF(D20:D24,"✅*")+COUNTIF(D32:D38,"✅*") -> 23 | B28: =COUNTIF(D6:D16,"❌*")+COUNTIF(D20:D24,"❌*")+COUNTIF(D32:D38,"❌*") -> 0 | C28: =COUNTIF(D6:D16,"⚠️*")+COUNTIF(D20:D24,"⚠️*")+COUNTIF(D32:D38,"⚠️*") -> 0 | D28: =IF(B28=0,IF(C28=0,"✅ ALL PASS","⚠️ WARNINGS"),"❌ FAILURES") -> ✅ ALL PASS
A30: CROSS-SHEET CONSISTENCY CHECKS
A31: Test | B31: Sheet A | C31: Sheet B | D31: Status | E31: Detail
A32: CAGR: Dashboard ↔ Analytics | B32: =Dashboard!H3 -> 0.14885493 | C32: =Analytics!E6 -> 0.14885493 | D32: =IF(ABS(B32-C32)<0.0001,"✅ PASS","❌ FAIL") -> ✅ PASS | E32: Portfolio CAGR must match across Dashboard and Analytics
A33: Beta: Dashboard ↔ Risk Analytics | B33: =Dashboard!S3 -> 1.4726694 | C33: ='Risk Analytics'!C9 -> 1.4726694 | D33: =IF(ABS(B33-C33)<0.001,"✅ PASS","❌ FAIL") -> ✅ PASS | E33: Weighted portfolio beta must match between Dashboard KPI and Risk Analytics
A34: Sharpe: Dashboard ↔ Risk Analytics | B34: =Dashboard!O3 -> 0.46593002 | C34: ='Risk Analytics'!C18 -> 0.46593002 | D34: =IF(ABS(B34-C34)<0.001,"✅ PASS","❌ FAIL") -> ✅ PASS | E34: Sharpe Ratio must match between Dashboard KPI and Risk Analytics
A35: Treynor: Dashboard ↔ Risk Analytics | B35: =Dashboard!T3 -> 0.072219153 | C35: ='Risk Analytics'!C15 -> 0.072219153 | D35: =IF(ABS(B35-C35)<0.0001,"✅ PASS","❌ FAIL") -> ✅ PASS | E35: Treynor Ratio must match between Dashboard and Risk Analytics
A36: CAPM: E(Rp) = Rf + βp(Rm-Rf) | B36: ='Risk Analytics'!C10 -> 0.12717849 | C36: ='Risk Analytics'!C6+'Risk Analytics'!C9*('Risk Analytics'!C7-'Risk Analytics'!C6) -> 0.12717849 | D36: =IF(ABS(B36-C36)<0.0001,"✅ PASS","❌ FAIL") -> ✅ PASS | E36: CAPM expected return formula: Rf + βp × ERP must be internally consistent
A37: Jensen's α = Rp - E(Rp) | B37: ='Risk Analytics'!C11 -> 0.021676445 | C37: =Analytics!E6-'Risk Analytics'!C10 -> 0.021676445 | D37: =IF(ABS(B37-C37)<0.0001,"✅ PASS","❌ FAIL") -> ✅ PASS | E37: Alpha = Actual CAGR minus CAPM expected return
A38: Risk decomp weights sum to 100% | B38: 1 | C38: ='Risk Analytics'!C55 -> 1 | D38: =IF(ABS(C38-1)<0.001,"✅ PASS","❌ FAIL") -> ✅ PASS | E38: Stock weights in risk decomposition table must sum to 100%

Sheet Optimization
A1: BLACK-LITTERMAN PORTFOLIO OPTIMIZATION
A2: Bayesian framework combining market equilibrium with investor views — Black & Litterman (1992), Goldman Sachs
A4: MODEL PARAMETERS
A5: Parameter | B5: Value | C5: Description
A6: Risk-Free Rate (Rf) | B6: ='Risk Analytics'!C6 -> 0.0425 | C6: Linked from Risk Analytics
A7: Risk Aversion (δ) | B7: 2.5 | C7: Market consensus ~2.5 (He & Litterman, 1999)
A8: Tau (τ) — Uncertainty | B8: 0.05 | C8: Proportional to (1/T). Lower = more certain about equilibrium
A10: EQUILIBRIUM WEIGHTS & IMPLIED RETURNS
A11: Ticker | B11: Current Wt | C11: Beta (βi) | D11: CAPM E(Ri) | E11: Implied Eq. Return | F11: BL Optimal Wt | G11: Trade (Δ Wt)
A12: =Dashboard!N7 -> 0R2N | B12: =Dashboard!M7 -> 0.051357301 | C12: ='Risk Analytics'!D39 -> 0.412 | D12: ='Risk Analytics'!H39 -> 0.06619 | E12: =$B$6+$B$7*C12*0.155^2 -> 0.06724575 | F12: =B12*(1+(D12-E12)*10) -> 0.050815096 | G12: =F12-B12 -> -0.00054220471
A13: =Dashboard!N8 -> AAPL | B13: =Dashboard!M8 -> 0.046889262 | C13: ='Risk Analytics'!D40 -> 1.1035 | D13: ='Risk Analytics'!H40 -> 0.10595125 | E13: =$B$6+$B$7*C13*0.155^2 -> 0.10877897 | F13: =B13*(1+(D13-E13)*10) -> 0.045563366 | G13: =F13-B13 -> -0.0013258965
A14: =Dashboard!N9 -> AMD | B14: =Dashboard!M9 -> 0.077751595 | C14: ='Risk Analytics'!D41 -> 1.9919 | D14: ='Risk Analytics'!H41 -> 0.15703425 | E14: =$B$6+$B$7*C14*0.155^2 -> 0.16213849 | F14: =B14*(1+(D14-E14)*10) -> 0.073782964 | G14: =F14-B14 -> -0.0039686309
A15: =Dashboard!N10 -> AMZN | B15: =Dashboard!M10 -> 0.031795354 | C15: ='Risk Analytics'!D42 -> 1.3631 | D15: ='Risk Analytics'!H42 -> 0.12087825 | E15: =$B$6+$B$7*C15*0.155^2 -> 0.12437119 | F15: =B15*(1+(D15-E15)*10) -> 0.03068476 | G15: =F15-B15 -> -0.0011105938
A16: =Dashboard!N11 -> BA | B16: =Dashboard!M11 -> 0.031768582 | C16: ='Risk Analytics'!D43 -> 1.1786 | D16: ='Risk Analytics'!H43 -> 0.1102695 | E16: =$B$6+$B$7*C16*0.155^2 -> 0.11328966 | F16: =B16*(1+(D16-E16)*10) -> 0.030809119 | G16: =F16-B16 -> -0.00095946279
A17: =Dashboard!N12 -> BLK | B17: =Dashboard!M12 -> 0.036674855 | C17: ='Risk Analytics'!D44 -> 1.4875 | D17: ='Risk Analytics'!H44 -> 0.12803125 | E17: =$B$6+$B$7*C17*0.155^2 -> 0.13184297 | F17: =B17*(1+(D17-E17)*10) -> 0.035276912 | G17: =F17-B17 -> -0.0013979423
A18: =Dashboard!N13 -> C | B18: =Dashboard!M13 -> 0.053780726 | C18: ='Risk Analytics'!D45 -> 1.1155 | D18: ='Risk Analytics'!H45 -> 0.10664125 | E18: =$B$6+$B$7*C18*0.155^2 -> 0.10949972 | F18: =B18*(1+(D18-E18)*10) -> 0.05224342 | G18: =F18-B18 -> -0.0015373052
A19: =Dashboard!N14 -> CVX | B19: =Dashboard!M14 -> 0.048281655 | C19: ='Risk Analytics'!D46 -> 0.6092 | D19: ='Risk Analytics'!H46 -> 0.077529 | E19: =$B$6+$B$7*C19*0.155^2 -> 0.079090075 | F19: =B19*(1+(D19-E19)*10) -> 0.047527943 | G19: =F19-B19 -> -0.00075371285
A20: =Dashboard!N15 -> F | B20: =Dashboard!M15 -> 0.028354674 | C20: ='Risk Analytics'!D47 -> 1.7561 | D20: ='Risk Analytics'!H47 -> 0.14347575 | E20: =$B$6+$B$7*C20*0.155^2 -> 0.14797576 | F20: =B20*(1+(D20-E20)*10) -> 0.027078712 | G20: =F20-B20 -> -0.0012759621
A21: =Dashboard!N16 -> GOOG | B21: =Dashboard!M16 -> 0.065883101 | C21: ='Risk Analytics'!D48 -> 1.1004 | D21: ='Risk Analytics'!H48 -> 0.105773 | E21: =$B$6+$B$7*C21*0.155^2 -> 0.10859278 | F21: =B21*(1+(D21-E21)*10) -> 0.064025346 | G21: =F21-B21 -> -0.0018577552
A22: =Dashboard!N17 -> HMC | B22: =Dashboard!M17 -> 0.020306274 | C22: ='Risk Analytics'!D49 -> 0.468 | D22: ='Risk Analytics'!H49 -> 0.06941 | E22: =$B$6+$B$7*C22*0.155^2 -> 0.07060925 | F22: =B22*(1+(D22-E22)*10) -> 0.020062751 | G22: =F22-B22 -> -0.00024352299
A23: =Dashboard!N18 -> JPM | B23: =Dashboard!M18 -> 0.055350051 | C23: ='Risk Analytics'!D50 -> 1.0615 | D23: ='Risk Analytics'!H50 -> 0.10353625 | E23: =$B$6+$B$7*C23*0.155^2 -> 0.10625634 | F23: =B23*(1+(D23-E23)*10) -> 0.053844478 | G23: =F23-B23 -> -0.0015055733
... A27: =Dashboard!N22 -> WMT | B27: =Dashboard!M22 -> 0.076046083 | C27: ='Risk Analytics'!D54 -> 0.6682 | D27: ='Risk Analytics'!H54 -> 0.0809215 | E27: =$B$6+$B$7*C27*0.155^2 -> 0.082633763 | F27: =B27*(1+(D27-E27)*10) -> 0.074743974 | G27: =F27-B27 -> -0.0013021086
A29: INVESTOR VIEWS (User Input)
A30: View # | B30: Description | C30: Expected Excess Return | D30: Confidence | E30: Status
A31: View 1 | B31: NVDA outperforms market by 10% | C31: 0.1 | D31: 0.75 | E31: Active
A32: View 2 | B32: MSFT (via META proxy) outperforms AAPL by 5% | C32: 0.05 | D32: 0.6 | E32: Active
A33: View 3 | B33: Financials (JPM, C, BLK) rally +8% | C33: 0.08 | D33: 0.5 | E33: Active
A34: View 4 | B34: (Enter your view here) | C34: 0 | D34: 0 | E34: Inactive
A35: View 5 | B35: (Enter your view here) | C35: 0 | D35: 0 | E35: Inactive
A37: VIEW-ADJUSTED REBALANCING TRADE LIST
A38: Ticker | B38: Current $ | C38: Target Wt | D38: Target $ | E38: Trade $ | F38: Action
A39: =A12 -> 0R2N | B39: =B12*SUM(Dashboard!G7:'Dashboard'!G22) -> 15596.205 | C39: =F12/SUM(F$12:F$27) -> 0.052807917 | D39: =C39*SUM(Dashboard!G7:'Dashboard'!G22) -> 16036.729 | E39: =D39-B39 -> 440.52354 | F39: =IF(ABS(E39)<500,"HOLD",IF(E39>0,"BUY "&TEXT(E39,"$#,##0"),"SELL "&TEXT(ABS(E39),"$#,##0"))) -> HOLD
A40: =A13 -> AAPL | B40: =B13*SUM(Dashboard!G7:'Dashboard'!G22) -> 14239.349 | C40: =F13/SUM(F$12:F$27) -> 0.047350228 | D40: =C40*SUM(Dashboard!G7:'Dashboard'!G22) -> 14379.336 | E40: =D40-B40 -> 139.98644 | F40: =IF(ABS(E40)<500,"HOLD",IF(E40>0,"BUY "&TEXT(E40,"$#,##0"),"SELL "&TEXT(ABS(E40),"$#,##0"))) -> HOLD
A41: =A14 -> AMD | B41: =B14*SUM(Dashboard!G7:'Dashboard'!G22) -> 23611.634 | C41: =F14/SUM(F$12:F$27) -> 0.076676518 | D41: =C41*SUM(Dashboard!G7:'Dashboard'!G22) -> 23285.154 | E41: =D41-B41 -> -326.47994 | F41: =IF(ABS(E41)<500,"HOLD",IF(E41>0,"BUY "&TEXT(E41,"$#,##0"),"SELL "&TEXT(ABS(E41),"$#,##0"))) -> HOLD
A42: =A15 -> AMZN | B42: =B15*SUM(Dashboard!G7:'Dashboard'!G22) -> 9655.6252 | C42: =F15/SUM(F$12:F$27) -> 0.031888127 | D42: =C42*SUM(Dashboard!G7:'Dashboard'!G22) -> 9683.7987 | E42: =D42-B42 -> 28.173433 | F42: =IF(ABS(E42)<500,"HOLD",IF(E42>0,"BUY "&TEXT(E42,"$#,##0"),"SELL "&TEXT(ABS(E42),"$#,##0"))) -> HOLD
A43: =A16 -> BA | B43: =B16*SUM(Dashboard!G7:'Dashboard'!G22) -> 9647.4951 | C43: =F16/SUM(F$12:F$27) -> 0.032017363 | D43: =C43*SUM(Dashboard!G7:'Dashboard'!G22) -> 9723.0451 | E43: =D43-B43 -> 75.550011 | F43: =IF(ABS(E43)<500,"HOLD",IF(E43>0,"BUY "&TEXT(E43,"$#,##0"),"SELL "&TEXT(ABS(E43),"$#,##0"))) -> HOLD
A44: =A17 -> BLK | B44: =B17*SUM(Dashboard!G7:'Dashboard'!G22) -> 11137.434 | C44: =F17/SUM(F$12:F$27) -> 0.03666037 | D44: =C44*SUM(Dashboard!G7:'Dashboard'!G22) -> 11133.035 | E44: =D44-B44 -> -4.3986004 | F44: =IF(ABS(E44)<500,"HOLD",IF(E44>0,"BUY "&TEXT(E44,"$#,##0"),"SELL "&TEXT(ABS(E44),"$#,##0"))) -> HOLD
A45: =A18 -> C | B45: =B18*SUM(Dashboard!G7:'Dashboard'!G22) -> 16332.151 | C45: =F18/SUM(F$12:F$27) -> 0.054292255 | D45: =C45*SUM(Dashboard!G7:'Dashboard'!G22) -> 16487.493 | E45: =D45-B45 -> 155.3416 | F45: =IF(ABS(E45)<500,"HOLD",IF(E45>0,"BUY "&TEXT(E45,"$#,##0"),"SELL "&TEXT(ABS(E45),"$#,##0"))) -> HOLD
A46: =A19 -> CVX | B46: =B19*SUM(Dashboard!G7:'Dashboard'!G22) -> 14662.192 | C46: =F19/SUM(F$12:F$27) -> 0.04939185 | D46: =C46*SUM(Dashboard!G7:'Dashboard'!G22) -> 14999.336 | E46: =D46-B46 -> 337.14443 | F46: =IF(ABS(E46)<500,"HOLD",IF(E46>0,"BUY "&TEXT(E46,"$#,##0"),"SELL "&TEXT(ABS(E46),"$#,##0"))) -> HOLD
A47: =A20 -> F | B47: =B20*SUM(Dashboard!G7:'Dashboard'!G22) -> 8610.7582 | C47: =F20/SUM(F$12:F$27) -> 0.02814066 | D47: =C47*SUM(Dashboard!G7:'Dashboard'!G22) -> 8545.7665 | E47: =D47-B47 -> -64.991762 | F47: =IF(ABS(E47)<500,"HOLD",IF(E47>0,"BUY "&TEXT(E47,"$#,##0"),"SELL "&TEXT(ABS(E47),"$#,##0"))) -> HOLD
...

Sheet Dashboard
V1: Ticker | W1: Return % | X1: Weight % | Y1: Gain/Loss | Z1: Ann. Return | AA1: Ticker | AB1: Gain/Loss | AC1: Ticker | AD1: Ann. Return | AE1: Ticker | AF1: Weight
B2: PORTFOLIO VALUE | E2: COST BASIS | F2: UNREALISED P&L | G2: TOTAL RETURN | H2: ="CAGR ("&TEXT((MAX(Ledger[Date])-MIN(Ledger[Date]))/365.25,"0")&"YR)" -> CAGR (6YR) | I2: BEST STOCK | J2: WORST STOCK | K2: HHI INDEX | N2: DAILY P&L | O2: SHARPE RATIO | P2: WIN RATE | Q2: AVG RETURN | R2: WORST STOCK RETURN | S2: PORT. BETA | T2: TREYNOR | V2: =N7 -> 0R2N | W2: =L7 -> 0.97044958 | X2: =M7 -> 0.051357301 | Y2: =J7 -> 7681.156 | Z2: =R7 -> 0.1196519 | AA2: =N7 -> 0R2N | AB2: =J7 -> 7681.156 | AC2: =N7 -> 0R2N | AD2: =R7 -> 0.1196519 | AE2: =N7 -> 0R2N | AF2: =M7 -> 0.051357301
B3: =SUM(_xlfn.ANCHORARRAY(G7)) -> 303680.39 | E3: =SUM(G7:G22)-SUM(J7:J22) -> 132051.42 | F3: =SUM(J7:J22) -> 171628.96 | G3: =F3/E3 -> 1.2997131 | H3: =(B3/E3)^(1/((MAX(Ledger[Date])-MIN(Ledger[Date]))/365.25))-1 -> 0.14885493 | I3: ="▲ "&INDEX(_xlfn.ANCHORARRAY(B7),MATCH(MAX(J7:J22),J7:J22,0)) -> ▲ NVDA | J3: ="▼ "&INDEX(_xlfn.ANCHORARRAY(B7),MATCH(MIN(J7:J22),J7:J22,0)) -> ▼ HMC | K3: {=SUMPRODUCT((SUMIF(_xlfn.ANCHORARRAY(D7),_xlfn.UNIQUE(_xlfn.ANCHORARRAY(D7)),_xlfn.ANCHORARRAY(G7))/SUM(_xlfn.ANCHORARRAY(G7)))^2)} -> 0.18756228 | N3: =SUM(H7:H22) -> 14.5968 | O3: ='Risk Analytics'!C18 -> 0.46593002 | P3: =COUNTIF(J7:J22,">0")/COUNTA(J7:J22) -> 0.875 | Q3: =AVERAGE(L7:L22) -> 1.268515 | R3: =MIN(L7:L22) -> -0.13381728 | S3: ='Risk Analytics'!C9 -> 1.4726694 | T3: ='Risk Analytics'!C15 -> 0.072219153 | V3: =N8 -> AAPL | W3: =L8 -> 0.92640661 | X3: =M8 -> 0.046889262 | Y3: =J8 -> 6847.6858 | Z3: =R8 -> 0.11544245 | AA3: =N8 -> AAPL | AB3: =J8 -> 6847.6858 | AC3: =N8 -> AAPL | AD3: =R8 -> 0.11544245 | AE3: =N8 -> AAPL | AF3: =M8 -> 0.046889262
B4: SORTINO | D4: ='Risk Analytics'!C19 -> 3.0962339 | E4: INFO RATIO | F4: ='Risk Analytics'!C16 -> 0.18770861 | G4: ACTIVE SHARE | H4: ='Risk Analytics'!C62 -> 0.26307902 | I4: ALPHA (α) | J4: ='Risk Analytics'!C11 -> 0.021676445 | K4: M² | L4: ='Risk Analytics'!C68 -> 0.014719153 | N4: TREYNOR | O4: ='Risk Analytics'!C15 -> 0.072219153 | P4: CALMAR | Q4: ='Risk Analytics'!C20 -> 1.1123746 | R4: CF VaR 95% | S4: ='Risk Analytics'!C75 -> -0.27855525 | V4: =N9 -> AMD | W4: =L9 -> 2.1931096 | X4: =M9 -> 0.077751595 | Y4: =J9 -> 16217.076 | Z4: =R9 -> 0.21343486 | AA4: =N9 -> AMD | AB4: =J9 -> 16217.076 | AC4: =N9 -> AMD | AD4: =R9 -> 0.21343486 | AE4: =N9 -> AMD | AF4: =M9 -> 0.077751595
B5: ="CURRENT HOLDINGS · "&COUNTA(B7:B22)&" STOCKS · "&COUNTA(_xlfn.UNIQUE(D7:D22))&" INDUSTRIES" -> CURRENT HOLDINGS · 16 STOCKS · 10 INDUSTRIES | N5: FINANCIAL METRICS · PER-STOCK ANALYTICS · RISK ASSESSMENT | V5: =N10 -> AMZN | W5: =L10 -> 0.49216603 | X5: =M10 -> 0.031795354 | Y5: =J10 -> 3184.7467 | Z5: =R10 -> 0.0689636 | AA5: =N10 -> AMZN | AB5: =J10 -> 3184.7467 | AC5: =N10 -> AMZN | AD5: =R10 -> 0.0689636 | AE5: =N10 -> AMZN | AF5: =M10 -> 0.031795354
B6: Ticker | C6: Company | D6: Industry | E6: Units | F6: Current Price | G6: Market Value | H6: Today's Change | J6: Gain/(Loss) | K6: Last 12 Months | L6: Return % | M6: Weight % | N6: Stock | O6: Cost Basis | P6: Avg Buy Price | Q6: Price/Cost | R6: Ann. Return | S6: Risk Score | T6: Signal | V6: =N11 -> BA | W6: =L11 -> -0.031168065 | X6: =M11 -> 0.031768582 | Y6: =J11 -> -310.3673 | Z6: =R11 -> -0.0052622557 | AA6: =N11 -> BA | AB6: =J11 -> -310.3673 | AC6: =N11 -> BA | AD6: =R11 -> -0.0052622557 | AE6: =N11 -> BA | AF6: =M11 -> 0.031768582
B7: {=_xlfn._xlws.SORT(_xlfn.UNIQUE(Ledger[Ticker]))} -> 0R2N | C7: {=_FV(INDEX(Ledger[Stock],MATCH(_xlfn.ANCHORARRAY(B7),Ledger[Ticker],0)),"Name")} -> RTX CORPORATION | D7: {=_FV(INDEX(Ledger[Stock],MATCH(_xlfn.ANCHORARRAY(B7),Ledger[Ticker],0)),"Industry")} -> Aerospace & Defense | E7: {=SUMIF(Ledger[Ticker],_xlfn.ANCHORARRAY(B7),Ledger[Units])} -> 79.37 | F7: {=_FV(INDEX(Ledger[Stock],MATCH(_xlfn.ANCHORARRAY(B7),Ledger[Ticker],0)),"Price")} -> 196.5 | G7: {=_xlfn.ANCHORARRAY(E7)*_xlfn.ANCHORARRAY(F7)} -> 15596.205 | H7: {=_xlfn.ANCHORARRAY(F7)-_FV(INDEX(Ledger[Stock],MATCH(_xlfn.ANCHORARRAY(B7),Ledger[Ticker],0)),"Previous close",TRUE)} -> 1 | I7: {=_xlfn.ANCHORARRAY(H7)/(_xlfn.ANCHORARRAY(G7)-_xlfn.ANCHORARRAY(H7))} -> 6.4122273e-05 | J7: {=_xlfn.ANCHORARRAY(G7)-SUMIF(Ledger[Ticker],_xlfn.ANCHORARRAY(B7),Ledger[Transaction Amount])} -> 7681.156 | L7: =IF((G7-J7)=0,0,J7/(G7-J7)) -> 0.97044958 | M7: =G7/SUM(G7:G22) -> 0.051357301 | N7: {=_xlfn.ANCHORARRAY(B7)} -> 0R2N | O7: =G7-J7 -> 7915.049 | P7: =O7/E7 -> 99.723435 | Q7: =F7/P7 -> 1.9704496 | R7: =(F7/P7)^(1/((MAX(Ledger[Date])-MIN(Ledger[Date]))/365.25))-1 -> 0.1196519 | S7: =IF(OR(L7<0,R7<0,M7>0.2),"HIGH",IF(OR(L7<0.5,R7<0.05,M7>0.15),"MEDIUM","LOW")) -> LOW | T7: =IF(AND(R7>0.1,L7>1,Q7>1.5,S7="LOW"),"▲ STRONG",IF(OR(L7<0,R7<0),"▼ REVIEW","▶ HOLD")) -> ▶ HOLD | V7: =N12 -> BLK | W7: =L12 -> 0.28303688 | X7: =M12 -> 0.036674855 | Y7: =J12 -> 2456.9088 | Z7: =R12 -> 0.042403214 | AA7: =N12 -> BLK | AB7: =J12 -> 2456.9088 | AC7: =N12 -> BLK | AD7: =R12 -> 0.042403214 | AE7: =N12 -> BLK | AF7: =M12 -> 0.036674855
B8: AAPL | C8: APPLE INC. | D8: Computers, Phones & Household Electronics | E8: 54.94 | F8: 259.18 | G8: 14239.349 | H8: 3.26 | I8: 0.00022899547 | J8: 6847.6858 | L8: =IF((G8-J8)=0,0,J8/(G8-J8)) -> 0.92640661 | M8: =G8/SUM(G7:G22) -> 0.046889262 | N8: AAPL | O8: =G8-J8 -> 7391.6634 | P8: =O8/E8 -> 134.54065 | Q8: =F8/P8 -> 1.9264066 | R8: =(F8/P8)^(1/((MAX(Ledger[Date])-MIN(Ledger[Date]))/365.25))-1 -> 0.11544245 | S8: =IF(OR(L8<0,R8<0,M8>0.2),"HIGH",IF(OR(L8<0.5,R8<0.05,M8>0.15),"MEDIUM","LOW")) -> LOW | T8: =IF(AND(R8>0.1,L8>1,Q8>1.5,S8="LOW"),"▲ STRONG",IF(OR(L8<0,R8<0),"▼ REVIEW","▶ HOLD")) -> ▶ HOLD | V8: =N13 -> C | W8: =L13 -> 0.96659915 | X8: =M13 -> 0.053780726 | Y8: =J13 -> 8027.3826 | Z8: =R13 -> 0.11928704 | AA8: =N13 -> C | AB8: =J13 -> 8027.3826 | AC8: =N13 -> C | AD8: =R13 -> 0.11928704 | AE8: =N13 -> C | AF8: =M13 -> 0.053780726
B9: AMD | C9: ADVANCED MICRO DEVICES, INC. | D9: Semiconductors & Semiconductor Equipment | E9: 107.16 | F9: 220.34 | G9: 23611.634 | H9: 2.84 | I9: 0.00012029416 | J9: 16217.076 | L9: =IF((G9-J9)=0,0,J9/(G9-J9)) -> 2.1931096 | M9: =G9/SUM(G7:G22) -> 0.077751595 | N9: AMD | O9: =G9-J9 -> 7394.5581 | P9: =O9/E9 -> 69.004835 | Q9: =F9/P9 -> 3.1931096 | R9: =(F9/P9)^(1/((MAX(Ledger[Date])-MIN(Ledger[Date]))/365.25))-1 -> 0.21343486 | S9: =IF(OR(L9<0,R9<0,M9>0.2),"HIGH",IF(OR(L9<0.5,R9<0.05,M9>0.15),"MEDIUM","LOW")) -> LOW | T9: =IF(AND(R9>0.1,L9>1,Q9>1.5,S9="LOW"),"▲ STRONG",IF(OR(L9<0,R9<0),"▼ REVIEW","▶ HOLD")) -> ▲ STRONG | V9: =N14 -> CVX | W9: =L14 -> 0.48414783 | X9: =M14 -> 0.048281655 | Y9: =J14 -> 4782.9928 | Z9: =R14 -> 0.068004316 | AA9: =N14 -> CVX | AB9: =J14 -> 4782.9928 | AC9: =N14 -> CVX | AD9: =R14 -> 0.068004316 | AE9: =N14 -> CVX | AF9: =M14 -> 0.048281655
B10: AMZN | C10: AMAZON.COM, INC. | D10: Diversified Retail | E10: 45.45 | F10: 212.445 | G10: 9655.6252 | H10: 2.675 | I10: 0.00027711735 | J10: 3184.7467 | L10: =IF((G10-J10)=0,0,J10/(G10-J10)) -> 0.49216603 | M10: =G10/SUM(G7:G22) -> 0.031795354 | N10: AMZN | O10: =G10-J10 -> 6470.8786 | P10: =O10/E10 -> 142.37357 | Q10: =F10/P10 -> 1.492166 | R10: =(F10/P10)^(1/((MAX(Ledger[Date])-MIN(Ledger[Date]))/365.25))-1 -> 0.0689636 | S10: =IF(OR(L10<0,R10<0,M10>0.2),"HIGH",IF(OR(L10<0.5,R10<0.05,M10>0.15),"MEDIUM","LOW")) -> MEDIUM | T10: =IF(AND(R10>0.1,L10>1,Q10>1.5,S10="LOW"),"▲ STRONG",IF(OR(L10<0,R10<0),"▼ REVIEW","▶ HOLD")) -> ▶ HOLD | V10: =N15 -> F | W10: =L15 -> 0.088062562 | X10: =M15 -> 0.028354674 | Y10: =J15 -> 696.91345 | Z10: =R15 -> 0.014162585 | AA10: =N15 -> F | AB10: =J15 -> 696.91345 | AC10: =N15 -> F | AD10: =R15 -> 0.014162585 | AE10: =N15 -> F | AF10: =M15 -> 0.028354674
B11: BA | C11: THE BOEING COMPANY | D11: Aerospace & Defense | E11: 45.79 | F11: 210.69 | G11: 9647.4951 | H11: 2.47 | I11: 0.00025609057 | J11: -310.3673 | L11: =IF((G11-J11)=0,0,J11/(G11-J11)) -> -0.031168065 | M11: =G11/SUM(G7:G22) -> 0.031768582 | N11: BA | O11: =G11-J11 -> 9957.8624 | P11: =O11/E11 -> 217.46806 | Q11: =F11/P11 -> 0.96883194 | R11: =(F11/P11)^(1/((MAX(Ledger[Date])-MIN(Ledger[Date]))/365.25))-1 -> -0.0052622557 | S11: =IF(OR(L11<0,R11<0,M11>0.2),"HIGH",IF(OR(L11<0.5,R11<0.05,M11>0.15),"MEDIUM","LOW")) -> HIGH | T11: =IF(AND(R11>0.1,L11>1,Q11>1.5,S11="LOW"),"▲ STRONG",IF(OR(L11<0,R11<0),"▼ REVIEW","▶ HOLD")) -> ▼ REVIEW | V11: =N16 -> GOOG | W11: =L16 -> 1.5472763 | X11: =M16 -> 0.065883101 | Y11: =J16 -> 12152.975 | Z11: =R16 -> 0.16859468 | AA11: =N16 -> GOOG | AB11: =J16 -> 12152.975 | AC11: =N16 -> GOOG | AD11: =R16 -> 0.16859468 | AE11: =N16 -> GOOG | AF11: =M16 -> 0.065883101
B12: BLK | C12: BLACKROCK, INC. | D12: Investment Banking & Investment Services | E12: 11.55 | F12: 964.28 | G12: 11137.434 | H12: -2.28 | I12: -0.00020467312 | J12: 2456.9088 | L12: =IF((G12-J12)=0,0,J12/(G12-J12)) -> 0.28303688 | M12: =G12/SUM(G7:G22) -> 0.036674855 | N12: BLK | O12: =G12-J12 -> 8680.5252 | P12: =O12/E12 -> 751.56062 | Q12: =F12/P12 -> 1.2830369 | R12: =(F12/P12)^(1/((MAX(Ledger[Date])-MIN(Ledger[Date]))/365.25))-1 -> 0.042403214 | S12: =IF(OR(L12<0,R12<0,M12>0.2),"HIGH",IF(OR(L12<0.5,R12<0.05,M12>0.15),"MEDIUM","LOW")) -> MEDIUM | T12: =IF(AND(R12>0.1,L12>1,Q12>1.5,S12="LOW"),"▲ STRONG",IF(OR(L12<0,R12<0),"▼ REVIEW","▶ HOLD")) -> ▶ HOLD | V12: =N17 -> HMC | W12: =L17 -> -0.13381728 | X12: =M17 -> 0.020306274 | Y12: =J17 -> -952.6857 | Z12: =R17 -> -0.023653535 | AA12: =N17 -> HMC | AB12: =J17 -> -952.6857 | AC12: =N17 -> HMC | AD12: =R17 -> -0.023653535 | AE12: =N17 -> HMC | AF12: =M17 -> 0.020306274
B13: C | C13: CITIGROUP INC. | D13: Investment Banking & Investment Services | E13: 140.13 | F13: 116.55 | G13: 16332.151 | H13: 1.3 | I13: 7.9603932e-05 | J13: 8027.3826 | L13: =IF((G13-J13)=0,0,J13/(G13-J13)) -> 0.96659915 | M13: =G13/SUM(G7:G22) -> 0.053780726 | N13: C | O13: =G13-J13 -> 8304.7689 | P13: =O13/E13 -> 59.264746 | Q13: =F13/P13 -> 1.9665992 | R13: =(F13/P13)^(1/((MAX(Ledger[Date])-MIN(Ledger[Date]))/365.25))-1 -> 0.11928704 | S13: =IF(OR(L13<0,R13<0,M13>0.2),"HIGH",IF(OR(L13<0.5,R13<0.05,M13>0.15),"MEDIUM","LOW")) -> LOW | T13: =IF(AND(R13>0.1,L13>1,Q13>1.5,S13="LOW"),"▲ STRONG",IF(OR(L13<0,R13<0),"▼ REVIEW","▶ HOLD")) -> ▶ HOLD | V13: =N18 -> JPM | W13: =L18 -> 0.78225846 | X13: =M18 -> 0.055350051 | Y13: =J18 -> 7377.5872 | Z13: =R18 -> 0.10108008 | AA13: =N18 -> JPM | AB13: =J18 -> 7377.5872 | AC13: =N18 -> JPM | AD13: =R18 -> 0.10108008 | AE13: =N18 -> JPM | AF13: =M18 -> 0.055350051
B14: CVX | C14: CHEVRON CORPORATION | D14: Oil & Gas | E14: 74.35 | F14: 197.205 | G14: 14662.192 | H14: -1.765 | I14: -0.00012036315 | J14: 4782.9928 | L14: =IF((G14-J14)=0,0,J14/(G14-J14)) -> 0.48414783 | M14: =G14/SUM(G7:G22) -> 0.048281655 | N14: CVX | O14: =G14-J14 -> 9879.199 | P14: =O14/E14 -> 132.87423 | Q14: =F14/P14 -> 1.4841478 | R14: =(F14/P14)^(1/((MAX(Ledger[Date])-MIN(Ledger[Date]))/365.25))-1 -> 0.068004316 | S14: =IF(OR(L14<0,R14<0,M14>0.2),"HIGH",IF(OR(L14<0.5,R14<0.05,M14>0.15),"MEDIUM","LOW")) -> MEDIUM | T14: =IF(AND(R14>0.1,L14>1,Q14>1.5,S14="LOW"),"▲ STRONG",IF(OR(L14<0,R14<0),"▼ REVIEW","▶ HOLD")) -> ▶ HOLD | V14: =N19 -> META | W14: =L19 -> 0.98269703 | X14: =M19 -> 0.05430257 | Y14: =J19 -> 8173.3559 | Z14: =R19 -> 0.12080852 | AA14: =N19 -> META | AB14: =J19 -> 8173.3559 | AC14: =N19 -> META | AD14: =R19 -> 0.12080852 | AE14: =N19 -> META | AF14: =M19 -> 0.05430257
B15: F | C15: FORD MOTOR COMPANY | D15: Automobiles & Auto Parts | E15: 743.91 | F15: 11.575 | G15: 8610.7582 | H15: -0.025 | I15: -2.9033363e-06 | J15: 696.91345 | L15: =IF((G15-J15)=0,0,J15/(G15-J15)) -> 0.088062562 | M15: =G15/SUM(G7:G22) -> 0.028354674 | N15: F | O15: =G15-J15 -> 7913.8448 | P15: =O15/E15 -> 10.638175 | Q15: =F15/P15 -> 1.0880626 | R15: =(F15/P15)^(1/((MAX(Ledger[Date])-MIN(Ledger[Date]))/365.25))-1 -> 0.014162585 | S15: =IF(OR(L15<0,R15<0,M15>0.2),"HIGH",IF(OR(L15<0.5,R15<0.05,M15>0.15),"MEDIUM","LOW")) -> MEDIUM | T15: =IF(AND(R15>0.1,L15>1,Q15>1.5,S15="LOW"),"▲ STRONG",IF(OR(L15<0,R15<0),"▼ REVIEW","▶ HOLD")) -> ▶ HOLD | V15: =N20 -> NVDA | W15: =L20 -> 9.1481213 | X15: =M20 -> 0.29339824 | Y15: =J20 -> 80319.411 | Z15: =R20 -> 0.47127103 | AA15: =N20 -> NVDA | AB15: =J20 -> 80319.411 | AC15: =N20 -> NVDA | AD15: =R20 -> 0.47127103 | AE15: =N20 -> NVDA | AF15: =M20 -> 0.29339824
B16: GOOG | C16: ALPHABET INC. | D16: Software & IT Services | E16: 67.62 | F16: 295.88 | G16: 20007.406 | H16: 1.42 | I16: 7.0978757e-05 | J16: 12152.975 | L16: =IF((G16-J16)=0,0,J16/(G16-J16)) -> 1.5472763 | M16: =G16/SUM(G7:G22) -> 0.065883101 | N16: GOOG | O16: =G16-J16 -> 7854.4309 | P16: =O16/E16 -> 116.15544 | Q16: =F16/P16 -> 2.5472763 | R16: =(F16/P16)^(1/((MAX(Ledger[Date])-MIN(Ledger[Date]))/365.25))-1 -> 0.16859468 | S16: =IF(OR(L16<0,R16<0,M16>0.2),"HIGH",IF(OR(L16<0.5,R16<0.05,M16>0.15),"MEDIUM","LOW")) -> LOW | T16: =IF(AND(R16>0.1,L16>1,Q16>1.5,S16="LOW"),"▲ STRONG",IF(OR(L16<0,R16<0),"▼ REVIEW","▶ HOLD")) -> ▲ STRONG | V16: =N21 -> TM | W16: =L21 -> 0.26358854 | X16: =M21 -> 0.028059676 | Y16: =J21 -> 1777.5435 | Z16: =R21 -> 0.039753562 | AA16: =N21 -> TM | AB16: =J21 -> 1777.5435 | AC16: =N21 -> TM | AD16: =R21 -> 0.039753562 | AE16: =N21 -> TM | AF16: =M21 -> 0.028059676
B17: HMC | C17: HONDA MOTOR CO., LTD. | D17: Automobiles & Auto Parts | E17: 258.45 | F17: 23.86 | G17: 6166.617 | H17: -0.29 | I17: -4.7025194e-05 | J17: -952.6857 | L17: =IF((G17-J17)=0,0,J17/(G17-J17)) -> -0.13381728 | M17: =G17/SUM(G7:G22) -> 0.020306274 | N17: HMC | O17: =G17-J17 -> 7119.3027 | P17: =O17/E17 -> 27.546151 | Q17: =F17/P17 -> 0.86618272 | R17: =(F17/P17)^(1/((MAX(Ledger[Date])-MIN(Ledger[Date]))/365.25))-1 -> -0.023653535 | S17: =IF(OR(L17<0,R17<0,M17>0.2),"HIGH",IF(OR(L17<0.5,R17<0.05,M17>0.15),"MEDIUM","LOW")) -> HIGH | T17: =IF(AND(R17>0.1,L17>1,Q17>1.5,S17="LOW"),"▲ STRONG",IF(OR(L17<0,R17<0),"▼ REVIEW","▶ HOLD")) -> ▼ REVIEW | V17: =N22 -> WMT | W17: =L22 -> 1.3333052 | X17: =M22 -> 0.076046083 | Y17: =J22 -> 13196.283 | Z17: =R22 -> 0.15163433 | AA17: =N22 -> WMT | AB17: =J22 -> 13196.283 | AC17: =N22 -> WMT | AD17: =R22 -> 0.15163433 | AE17: =N22 -> WMT | AF17: =M22 -> 0.076046083
B18: JPM | C18: JPMORGAN CHASE & CO. | D18: Banking Services | E18: 56.84 | F18: 295.72 | G18: 16808.725 | H18: 2.62 | I18: 0.00015589573 | J18: 7377.5872 | L18: =IF((G18-J18)=0,0,J18/(G18-J18)) -> 0.78225846 | M18: =G18/SUM(G7:G22) -> 0.055350051 | N18: JPM | O18: =G18-J18 -> 9431.1376 | P18: =O18/E18 -> 165.92431 | Q18: =F18/P18 -> 1.7822585 | R18: =(F18/P18)^(1/((MAX(Ledger[Date])-MIN(Ledger[Date]))/365.25))-1 -> 0.10108008 | S18: =IF(OR(L18<0,R18<0,M18>0.2),"HIGH",IF(OR(L18<0.5,R18<0.05,M18>0.15),"MEDIUM","LOW")) -> LOW | T18: =IF(AND(R18>0.1,L18>1,Q18>1.5,S18="LOW"),"▲ STRONG",IF(OR(L18<0,R18<0),"▼ REVIEW","▶ HOLD")) -> ▶ HOLD
B19: META | C19: META PLATFORMS, INC. | D19: Software & IT Services | E19: 28.53 | F19: 578.01 | G19: 16490.625 | H19: 3.55 | I19: 0.00021532018 | J19: 8173.3559 | L19: =IF((G19-J19)=0,0,J19/(G19-J19)) -> 0.98269703 | M19: =G19/SUM(G7:G22) -> 0.05430257 | N19: META | O19: =G19-J19 -> 8317.2694 | P19: =O19/E19 -> 291.52714 | Q19: =F19/P19 -> 1.982697 | R19: =(F19/P19)^(1/((MAX(Ledger[Date])-MIN(Ledger[Date]))/365.25))-1 -> 0.12080852 | S19: =IF(OR(L19<0,R19<0,M19>0.2),"HIGH",IF(OR(L19<0.5,R19<0.05,M19>0.15),"MEDIUM","LOW")) -> LOW | T19: =IF(AND(R19>0.1,L19>1,Q19>1.5,S19="LOW"),"▲ STRONG",IF(OR(L19<0,R19<0),"▼ REVIEW","▶ HOLD")) -> ▶ HOLD
B20: NVDA | C20: NVIDIA CORPORATION | D20: Semiconductors & Semiconductor Equipment | E20: 503.13 | F20: 177.09 | G20: 89099.292 | H20: -0.3 | I20: -3.3670188e-06 | J20: 80319.411 | L20: =IF((G20-J20)=0,0,J20/(G20-J20)) -> 9.1481213 | M20: =G20/SUM(G7:G22) -> 0.29339824 | N20: NVDA | O20: =G20-J20 -> 8779.8804 | P20: =O20/E20 -> 17.450521 | Q20: =F20/P20 -> 10.148121 | R20: =(F20/P20)^(1/((MAX(Ledger[Date])-MIN(Ledger[Date]))/365.25))-1 -> 0.47127103 | S20: =IF(OR(L20<0,R20<0,M20>0.2),"HIGH",IF(OR(L20<0.5,R20<0.05,M20>0.15),"MEDIUM","LOW")) -> HIGH | T20: =IF(AND(R20>0.1,L20>1,Q20>1.5,S20="LOW"),"▲ STRONG",IF(OR(L20<0,R20<0),"▼ REVIEW","▶ HOLD")) -> ▶ HOLD
B21: TM | C21: TOYOTA MOTOR CORPORATION | D21: Automobiles & Auto Parts | E21: 41.67 | F21: 204.4918 | G21: 8521.1733 | H21: -2.5182 | I21: -0.00029543538 | J21: 1777.5435 | L21: =IF((G21-J21)=0,0,J21/(G21-J21)) -> 0.26358854 | M21: =G21/SUM(G7:G22) -> 0.028059676 | N21: TM | O21: =G21-J21 -> 6743.6298 | P21: =O21/E21 -> 161.83417 | Q21: =F21/P21 -> 1.2635885 | R21: =(F21/P21)^(1/((MAX(Ledger[Date])-MIN(Ledger[Date]))/365.25))-1 -> 0.039753562 | S21: =IF(OR(L21<0,R21<0,M21>0.2),"HIGH",IF(OR(L21<0.5,R21<0.05,M21>0.15),"MEDIUM","LOW")) -> MEDIUM | T21: =IF(AND(R21>0.1,L21>1,Q21>1.5,S21="LOW"),"▲ STRONG",IF(OR(L21<0,R21<0),"▼ REVIEW","▶ HOLD")) -> ▶ HOLD
B22: WMT | C22: WALMART INC. | D22: Food & Drug Retailing | E22: 182.66 | F22: 126.43 | G22: 23093.704 | H22: 0.64 | I22: 2.7713949e-05 | J22: 13196.283 | L22: =IF((G22-J22)=0,0,J22/(G22-J22)) -> 1.3333052 | M22: =G22/SUM(G7:G22) -> 0.076046083 | N22: WMT | O22: =G22-J22 -> 9897.421 | P22: =O22/E22 -> 54.184939 | Q22: =F22/P22 -> 2.3333052 | R22: =(F22/P22)^(1/((MAX(Ledger[Date])-MIN(Ledger[Date]))/365.25))-1 -> 0.15163433 | S22: =IF(OR(L22<0,R22<0,M22>0.2),"HIGH",IF(OR(L22<0.5,R22<0.05,M22>0.15),"MEDIUM","LOW")) -> LOW | T22: =IF(AND(R22>0.1,L22>1,Q22>1.5,S22="LOW"),"▲ STRONG",IF(OR(L22<0,R22<0),"▼ REVIEW","▶ HOLD")) -> ▲ STRONG
B24: COST BASIS | D24: TOP HOLDING | F24: TOP 3 CONC. | H24: AVG RETURN | J24: PROFITABLE | L24: HHI INDEX | N24: ▲ STRONG | O24: ▶ HOLD | P24: ▼ REVIEW | Q24: PROFIT FACTOR | R24: SORTINO RATIO | S24: CALMAR RATIO | T24: PORT. GRADE
B25: =SUM(_xlfn.ANCHORARRAY(G7))-SUM(_xlfn.ANCHORARRAY(J7)) -> 132051.42 | D25: =INDEX(_xlfn.ANCHORARRAY(B7),MATCH(MAX(M7:M22),M7:M22,0))&" "&TEXT(MAX(M7:M22),"0.0%") -> NVDA 29.3% | F25: =LARGE(M7:M22,1)+LARGE(M7:M22,2)+LARGE(M7:M22,3) -> 0.44719592 | H25: =AVERAGE(L7:L22) -> 1.268515 | J25: =COUNTIF(J7:J22,">0")&" / "&COUNTA(J7:J22) -> 14 / 16 | L25: {=SUMPRODUCT((SUMIF(_xlfn.ANCHORARRAY(D7),_xlfn.UNIQUE(_xlfn.ANCHORARRAY(D7)),_xlfn.ANCHORARRAY(G7))/SUM(_xlfn.ANCHORARRAY(G7)))^2)} -> 0.18756228 | N25: =COUNTIF(T7:T22,"*STRONG*") -> 3 | O25: =COUNTIF(T7:T22,"*HOLD*") -> 11 | P25: =COUNTIF(T7:T22,"*REVIEW*") -> 2 | Q25: =SUMIF(J7:J22,">0")/ABS(SUMIF(J7:J22,"<0")) -> 136.88421 | R25: {=(AVERAGE(L7:L22)-0.05)/SQRT(SUMPRODUCT((L7:L22<0)*(L7:L22)^2)/COUNTA(L7:L22))} -> 35.473741 | S25: =H3/ABS(R3) -> 1.1123746 | T25: =Analytics!H44 -> B+
B28: SECTOR ALLOCATION | H28: REBALANCING ANALYSIS
B29: Industry | D29: Market Value | E29: Weight % | F29: HHI Contrib. | H29: Stock | I29: Current Wt. | J29: Equal Wt. | K29: Deviation | L29: Action | M29: Vol Band (±) | N29: Tax Flag | O29: Vol Action
B30: {=_xlfn.UNIQUE(_xlfn.ANCHORARRAY(D7))} -> Aerospace & Defense | D30: {=SUMIF(_xlfn.ANCHORARRAY(D7),_xlfn.ANCHORARRAY(B30),_xlfn.ANCHORARRAY(G7))} -> 25243.7 | E30: =D30/SUM(D$30:D$39) -> 0.083125883 | F30: =E30^2 -> 0.0069099124 | H30: =N7 -> 0R2N | I30: =M7 -> 0.051357301 | J30: =1/COUNTA(M$7:M$22) -> 0.0625 | K30: =M7-(1/COUNTA(M$7:M$22)) -> -0.011142699 | L30: =IF(ABS(K30)>0.1,IF(K30>0,"🔻 TRIM","🔺 ADD"),IF(ABS(K30)>0.03,IF(K30>0,"▿ trim","▵ add"),"✔ OK")) -> ✔ OK | M30: =0.5*IFERROR(INDEX('Risk Analytics'!D$39:D$54,MATCH(H30,'Risk Analytics'!B$39:B$54,0))*0.155,0.08) -> 0.03193 | N30: =IF(AND(L30<>"✔ OK",COUNTIFS(Ledger[Ticker],H30,Ledger[Transaction Type],"Buy",Ledger[Holding Days],"<365")>0),"⚠ HIGH TAX","") | O30: =IF(ABS(K30)>M30,IF(K30>0,"🔻 VOL-TRIM","🔺 VOL-ADD"),"✔ WITHIN BAND") -> ✔ WITHIN BAND
B31: Computers, Phones & Household Electronics | D31: 14239.349 | E31: =D31/SUM(D$30:D$39) -> 0.046889262 | F31: =E31^2 -> 0.0021986029 | H31: =N8 -> AAPL | I31: =M8 -> 0.046889262 | J31: =1/COUNTA(M$7:M$22) -> 0.0625 | K31: =M8-(1/COUNTA(M$7:M$22)) -> -0.015610738 | L31: =IF(ABS(K31)>0.1,IF(K31>0,"🔻 TRIM","🔺 ADD"),IF(ABS(K31)>0.03,IF(K31>0,"▿ trim","▵ add"),"✔ OK")) -> ✔ OK | M31: =0.5*IFERROR(INDEX('Risk Analytics'!D$39:D$54,MATCH(H31,'Risk Analytics'!B$39:B$54,0))*0.155,0.08) -> 0.08552125 | N31: =IF(AND(L31<>"✔ OK",COUNTIFS(Ledger[Ticker],H31,Ledger[Transaction Type],"Buy",Ledger[Holding Days],"<365")>0),"⚠ HIGH TAX","") | O31: =IF(ABS(K31)>M31,IF(K31>0,"🔻 VOL-TRIM","🔺 VOL-ADD"),"✔ WITHIN BAND") -> ✔ WITHIN BAND
B32: Semiconductors & Semiconductor Equipment | D32: 112710.93 | E32: =D32/SUM(D$30:D$39) -> 0.37114984 | F32: =E32^2 -> 0.1377522 | H32: =N9 -> AMD | I32: =M9 -> 0.077751595 | J32: =1/COUNTA(M$7:M$22) -> 0.0625 | K32: =M9-(1/COUNTA(M$7:M$22)) -> 0.015251595 | L32: =IF(ABS(K32)>0.1,IF(K32>0,"🔻 TRIM","🔺 ADD"),IF(ABS(K32)>0.03,IF(K32>0,"▿ trim","▵ add"),"✔ OK")) -> ✔ OK | M32: =0.5*IFERROR(INDEX('Risk Analytics'!D$39:D$54,MATCH(H32,'Risk Analytics'!B$39:B$54,0))*0.155,0.08) -> 0.15437225 | N32: =IF(AND(L32<>"✔ OK",COUNTIFS(Ledger[Ticker],H32,Ledger[Transaction Type],"Buy",Ledger[Holding Days],"<365")>0),"⚠ HIGH TAX","") | O32: =IF(ABS(K32)>M32,IF(K32>0,"🔻 VOL-TRIM","🔺 VOL-ADD"),"✔ WITHIN BAND") -> ✔ WITHIN BAND
B33: Diversified Retail | D33: 9655.6252 | E33: =D33/SUM(D$30:D$39) -> 0.031795354 | F33: =E33^2 -> 0.0010109445 | H33: =N10 -> AMZN | I33: =M10 -> 0.031795354 | J33: =1/COUNTA(M$7:M$22) -> 0.0625 | K33: =M10-(1/COUNTA(M$7:M$22)) -> -0.030704646 | L33: =IF(ABS(K33)>0.1,IF(K33>0,"🔻 TRIM","🔺 ADD"),IF(ABS(K33)>0.03,IF(K33>0,"▿ trim","▵ add"),"✔ OK")) -> ▵ add | M33: =0.5*IFERROR(INDEX('Risk Analytics'!D$39:D$54,MATCH(H33,'Risk Analytics'!B$39:B$54,0))*0.155,0.08) -> 0.10564025 | N33: =IF(AND(L33<>"✔ OK",COUNTIFS(Ledger[Ticker],H33,Ledger[Transaction Type],"Buy",Ledger[Holding Days],"<365")>0),"⚠ HIGH TAX","") | O33: =IF(ABS(K33)>M33,IF(K33>0,"🔻 VOL-TRIM","🔺 VOL-ADD"),"✔ WITHIN BAND") -> ✔ WITHIN BAND
B34: Investment Banking & Investment Services | D34: 27469.586 | E34: =D34/SUM(D$30:D$39) -> 0.09045558 | F34: =E34^2 -> 0.008182212 | H34: =N11 -> BA | I34: =M11 -> 0.031768582 | J34: =1/COUNTA(M$7:M$22) -> 0.0625 | K34: =M11-(1/COUNTA(M$7:M$22)) -> -0.030731418 | L34: =IF(ABS(K34)>0.1,IF(K34>0,"🔻 TRIM","🔺 ADD"),IF(ABS(K34)>0.03,IF(K34>0,"▿ trim","▵ add"),"✔ OK")) -> ▵ add | M34: =0.5*IFERROR(INDEX('Risk Analytics'!D$39:D$54,MATCH(H34,'Risk Analytics'!B$39:B$54,0))*0.155,0.08) -> 0.0913415 | N34: =IF(AND(L34<>"✔ OK",COUNTIFS(Ledger[Ticker],H34,Ledger[Transaction Type],"Buy",Ledger[Holding Days],"<365")>0),"⚠ HIGH TAX","") | O34: =IF(ABS(K34)>M34,IF(K34>0,"🔻 VOL-TRIM","🔺 VOL-ADD"),"✔ WITHIN BAND") -> ✔ WITHIN BAND
B35: Oil & Gas | D35: 14662.192 | E35: =D35/SUM(D$30:D$39) -> 0.048281655 | F35: =E35^2 -> 0.0023311182 | H35: =N12 -> BLK | I35: =M12 -> 0.036674855 | J35: =1/COUNTA(M$7:M$22) -> 0.0625 | K35: =M12-(1/COUNTA(M$7:M$22)) -> -0.025825145 | L35: =IF(ABS(K35)>0.1,IF(K35>0,"🔻 TRIM","🔺 ADD"),IF(ABS(K35)>0.03,IF(K35>0,"▿ trim","▵ add"),"✔ OK")) -> ✔ OK | M35: =0.5*IFERROR(INDEX('Risk Analytics'!D$39:D$54,MATCH(H35,'Risk Analytics'!B$39:B$54,0))*0.155,0.08) -> 0.11528125 | N35: =IF(AND(L35<>"✔ OK",COUNTIFS(Ledger[Ticker],H35,Ledger[Transaction Type],"Buy",Ledger[Holding Days],"<365")>0),"⚠ HIGH TAX","") | O35: =IF(ABS(K35)>M35,IF(K35>0,"🔻 VOL-TRIM","🔺 VOL-ADD"),"✔ WITHIN BAND") -> ✔ WITHIN BAND
B36: Automobiles & Auto Parts | D36: 23298.549 | E36: =D36/SUM(D$30:D$39) -> 0.076720624 | F36: =E36^2 -> 0.0058860541 | H36: =N13 -> C | I36: =M13 -> 0.053780726 | J36: =1/COUNTA(M$7:M$22) -> 0.0625 | K36: =M13-(1/COUNTA(M$7:M$22)) -> -0.0087192744 | L36: =IF(ABS(K36)>0.1,IF(K36>0,"🔻 TRIM","🔺 ADD"),IF(ABS(K36)>0.03,IF(K36>0,"▿ trim","▵ add"),"✔ OK")) -> ✔ OK | M36: =0.5*IFERROR(INDEX('Risk Analytics'!D$39:D$54,MATCH(H36,'Risk Analytics'!B$39:B$54,0))*0.155,0.08) -> 0.08645125 | N36: =IF(AND(L36<>"✔ OK",COUNTIFS(Ledger[Ticker],H36,Ledger[Transaction Type],"Buy",Ledger[Holding Days],"<365")>0),"⚠ HIGH TAX","") | O36: =IF(ABS(K36)>M36,IF(K36>0,"🔻 VOL-TRIM","🔺 VOL-ADD"),"✔ WITHIN BAND") -> ✔ WITHIN BAND
B37: Software & IT Services | D37: 36498.031 | E37: =D37/SUM(D$30:D$39) -> 0.12018567 | F37: =E37^2 -> 0.014444595 | H37: =N14 -> CVX | I37: =M14 -> 0.048281655 | J37: =1/COUNTA(M$7:M$22) -> 0.0625 | K37: =M14-(1/COUNTA(M$7:M$22)) -> -0.014218345 | L37: =IF(ABS(K37)>0.1,IF(K37>0,"🔻 TRIM","🔺 ADD"),IF(ABS(K37)>0.03,IF(K37>0,"▿ trim","▵ add"),"✔ OK")) -> ✔ OK | M37: =0.5*IFERROR(INDEX('Risk Analytics'!D$39:D$54,MATCH(H37,'Risk Analytics'!B$39:B$54,0))*0.155,0.08) -> 0.047213 | N37: =IF(AND(L37<>"✔ OK",COUNTIFS(Ledger[Ticker],H37,Ledger[Transaction Type],"Buy",Ledger[Holding Days],"<365")>0),"⚠ HIGH TAX","") | O37: =IF(ABS(K37)>M37,IF(K37>0,"🔻 VOL-TRIM","🔺 VOL-ADD"),"✔ WITHIN BAND") -> ✔ WITHIN BAND
B38: Banking Services | D38: 16808.725 | E38: =D38/SUM(D$30:D$39) -> 0.055350051 | F38: =E38^2 -> 0.0030636281 | H38: =N15 -> F | I38: =M15 -> 0.028354674 | J38: =1/COUNTA(M$7:M$22) -> 0.0625 | K38: =M15-(1/COUNTA(M$7:M$22)) -> -0.034145326 | L38: =IF(ABS(K38)>0.1,IF(K38>0,"🔻 TRIM","🔺 ADD"),IF(ABS(K38)>0.03,IF(K38>0,"▿ trim","▵ add"),"✔ OK")) -> ▵ add | M38: =0.5*IFERROR(INDEX('Risk Analytics'!D$39:D$54,MATCH(H38,'Risk Analytics'!B$39:B$54,0))*0.155,0.08) -> 0.13609775 | N38: =IF(AND(L38<>"✔ OK",COUNTIFS(Ledger[Ticker],H38,Ledger[Transaction Type],"Buy",Ledger[Holding Days],"<365")>0),"⚠ HIGH TAX","") | O38: =IF(ABS(K38)>M38,IF(K38>0,"🔻 VOL-TRIM","🔺 VOL-ADD"),"✔ WITHIN BAND") -> ✔ WITHIN BAND
B39: Food & Drug Retailing | D39: 23093.704 | E39: =D39/SUM(D$30:D$39) -> 0.076046083 | F39: =E39^2 -> 0.0057830067 | H39: =N16 -> GOOG | I39: =M16 -> 0.065883101 | J39: =1/COUNTA(M$7:M$22) -> 0.0625 | K39: =M16-(1/COUNTA(M$7:M$22)) -> 0.0033831012 | L39: =IF(ABS(K39)>0.1,IF(K39>0,"🔻 TRIM","🔺 ADD"),IF(ABS(K39)>0.03,IF(K39>0,"▿ trim","▵ add"),"✔ OK")) -> ✔ OK | M39: =0.5*IFERROR(INDEX('Risk Analytics'!D$39:D$54,MATCH(H39,'Risk Analytics'!B$39:B$54,0))*0.155,0.08) -> 0.085281 | N39: =IF(AND(L39<>"✔ OK",COUNTIFS(Ledger[Ticker],H39,Ledger[Transaction Type],"Buy",Ledger[Holding Days],"<365")>0),"⚠ HIGH TAX","") | O39: =IF(ABS(K39)>M39,IF(K39>0,"🔻 VOL-TRIM","🔺 VOL-ADD"),"✔ WITHIN BAND") -> ✔ WITHIN BAND
H40: =N17 -> HMC | I40: =M17 -> 0.020306274 | J40: =1/COUNTA(M$7:M$22) -> 0.0625 | K40: =M17-(1/COUNTA(M$7:M$22)) -> -0.042193726 | L40: =IF(ABS(K40)>0.1,IF(K40>0,"🔻 TRIM","🔺 ADD"),IF(ABS(K40)>0.03,IF(K40>0,"▿ trim","▵ add"),"✔ OK")) -> ▵ add | M40: =0.5*IFERROR(INDEX('Risk Analytics'!D$39:D$54,MATCH(H40,'Risk Analytics'!B$39:B$54,0))*0.155,0.08) -> 0.03627 | N40: =IF(AND(L40<>"✔ OK",COUNTIFS(Ledger[Ticker],H40,Ledger[Transaction Type],"Buy",Ledger[Holding Days],"<365")>0),"⚠ HIGH TAX","") | O40: =IF(ABS(K40)>M40,IF(K40>0,"🔻 VOL-TRIM","🔺 VOL-ADD"),"✔ WITHIN BAND") -> 🔺 VOL-ADD
B41: ="📊 Portfolio: "&TEXT(B3,"$#,##0")&" | "&TEXT(G3,"0.0%")&" total return ("&TEXT(H3,"0.0%")&" CAGR) | Sharpe "&TEXT(O3,"0.00")&" | Sortino "&TEXT(D4,"0.00")&" | "&COUNTIF(T7:T22,"▲ STRONG")&" strong, "&COUNTIF(T7:T22,"▼ REVIEW")&" review | "&TEXT(S4,"0.0%")&" CF VaR95 | "&IF(J4>0,"Positive","Negative")&" alpha" -> 📊 Portfolio: $303,680 | 130.0% total return (14.9% CAGR) | Sharpe 0.47 | Sortino 3.10 | 3 strong, 2 review | -27.9% CF VaR95 | Positive alpha | H41: =N18 -> JPM | I41: =M18 -> 0.055350051 | J41: =1/COUNTA(M$7:M$22) -> 0.0625 | K41: =M18-(1/COUNTA(M$7:M$22)) -> -0.0071499492 | L41: =IF(ABS(K41)>0.1,IF(K41>0,"🔻 TRIM","🔺 ADD"),IF(ABS(K41)>0.03,IF(K41>0,"▿ trim","▵ add"),"✔ OK")) -> ✔ OK | M41: =0.5*IFERROR(INDEX('Risk Analytics'!D$39:D$54,MATCH(H41,'Risk Analytics'!B$39:B$54,0))*0.155,0.08) -> 0.08226625 | N41: =IF(AND(L41<>"✔ OK",COUNTIFS(Ledger[Ticker],H41,Ledger[Transaction Type],"Buy",Ledger[Holding Days],"<365")>0),"⚠ HIGH TAX","") | O41: =IF(ABS(K41)>M41,IF(K41>0,"🔻 VOL-TRIM","🔺 VOL-ADD"),"✔ WITHIN BAND") -> ✔ WITHIN BAND
H42: =N19 -> META | I42: =M19 -> 0.05430257 | J42: =1/COUNTA(M$7:M$22) -> 0.0625 | K42: =M19-(1/COUNTA(M$7:M$22)) -> -0.0081974304 | L42: =IF(ABS(K42)>0.1,IF(K42>0,"🔻 TRIM","🔺 ADD"),IF(ABS(K42)>0.03,IF(K42>0,"▿ trim","▵ add"),"✔ OK")) -> ✔ OK | M42: =0.5*IFERROR(INDEX('Risk Analytics'!D$39:D$54,MATCH(H42,'Risk Analytics'!B$39:B$54,0))*0.155,0.08) -> 0.10061825 | N42: =IF(AND(L42<>"✔ OK",COUNTIFS(Ledger[Ticker],H42,Ledger[Transaction Type],"Buy",Ledger[Holding Days],"<365")>0),"⚠ HIGH TAX","") | O42: =IF(ABS(K42)>M42,IF(K42>0,"🔻 VOL-TRIM","🔺 VOL-ADD"),"✔ WITHIN BAND") -> ✔ WITHIN BAND
H43: =N20 -> NVDA | I43: =M20 -> 0.29339824 | J43: =1/COUNTA(M$7:M$22) -> 0.0625 | K43: =M20-(1/COUNTA(M$7:M$22)) -> 0.23089824 | L43: =IF(ABS(K43)>0.1,IF(K43>0,"🔻 TRIM","🔺 ADD"),IF(ABS(K43)>0.03,IF(K43>0,"▿ trim","▵ add"),"✔ OK")) -> 🔻 TRIM | M43: =0.5*IFERROR(INDEX('Risk Analytics'!D$39:D$54,MATCH(H43,'Risk Analytics'!B$39:B$54,0))*0.155,0.08) -> 0.18186925 | N43: =IF(AND(L43<>"✔ OK",COUNTIFS(Ledger[Ticker],H43,Ledger[Transaction Type],"Buy",Ledger[Holding Days],"<365")>0),"⚠ HIGH TAX","") | O43: =IF(ABS(K43)>M43,IF(K43>0,"🔻 VOL-TRIM","🔺 VOL-ADD"),"✔ WITHIN BAND") -> 🔻 VOL-TRIM
...

Sheet WL Dashboard
B2: WATCHLIST DASHBOARD
B3: TOTAL MARKET CAP | C3: AVG P/E RATIO | D3: AVG BETA | E3: HIGHEST P/E | F3: LOWEST P/E | G3: TOP GAINER TODAY | H3: TOP LOSER TODAY | I3: STOCKS | J3: INDUSTRIES | K3: MEDIAN P/E
B4: =SUM(Watchlist!J2:INDEX(Watchlist!J:J,COUNTA(Watchlist!J:J))) -> 5465783557158 | C4: =AVERAGE(Watchlist!F2:INDEX(Watchlist!F:F,COUNTA(Watchlist!F:F))) -> 30.44653 | D4: =AVERAGE(Watchlist!E2:INDEX(Watchlist!E:E,COUNTA(Watchlist!E:E))) -> 0.98949 | E4: {=INDEX(Watchlist!B:B,MATCH(MAX(Watchlist!F$2:INDEX(Watchlist!F:F,COUNTA(Watchlist!F:F))),Watchlist!F$2:INDEX(Watchlist!F:F,COUNTA(Watchlist!F:F)),0)+1)&" "&TEXT(MAX(Watchlist!F$2:INDEX(Watchlist!F:F,COUNTA(Watchlist!F:F))),"0.0x")} -> AMD 84.6x | F4: {=INDEX(Watchlist!B:B,MATCH(MIN(Watchlist!F$2:INDEX(Watchlist!F:F,COUNTA(Watchlist!F:F))),Watchlist!F$2:INDEX(Watchlist!F:F,COUNTA(Watchlist!F:F)),0)+1)&" "&TEXT(MIN(Watchlist!F$2:INDEX(Watchlist!F:F,COUNTA(Watchlist!F:F))),"0.0x")} -> BAC 13.2x | G4: {="▲ "&INDEX(Watchlist!B:B,MATCH(MAX(Watchlist!G$2:INDEX(Watchlist!G:G,COUNTA(Watchlist!G:G))),Watchlist!G$2:INDEX(Watchlist!G:G,COUNTA(Watchlist!G:G)),0)+1)} -> ▲ AMD | H4: {="▼ "&INDEX(Watchlist!B:B,MATCH(MIN(Watchlist!G$2:INDEX(Watchlist!G:G,COUNTA(Watchlist!G:G))),Watchlist!G$2:INDEX(Watchlist!G:G,COUNTA(Watchlist!G:G)),0)+1)} -> ▼ MSFT | I4: =COUNTA(Watchlist!B2:INDEX(Watchlist!B:B,COUNTA(Watchlist!B:B))) -> 10 | J4: =COUNTA(_xlfn.UNIQUE(Watchlist!K2:INDEX(Watchlist!K:K,COUNTA(Watchlist!K:K)))) -> 9 | K4: =MEDIAN(Watchlist!F2:INDEX(Watchlist!F:F,COUNTA(Watchlist!F:F))) -> 22.813
B6: ="WATCHLIST · "&COUNTA(Watchlist!B2:B100)&" STOCKS · LIVE MARKET DATA · 52-WEEK ANALYSIS" -> WATCHLIST · 10 STOCKS · LIVE MARKET DATA · 52-WEEK ANALYSIS
B7: Ticker | C7: Industry | D7: Current Price | E7: Change ($) | F7: P/E Ratio | G7: Beta | H7: Market Cap | I7: 52W High | J7: 52W Low | K7: 52W Range % | L7: In Portfolio?
B8: =Watchlist!B3 -> MSFT | C8: =Watchlist!K3 -> Software & IT Services | D8: {=_FV(Watchlist!A3,"Price")} -> 371.44 | E8: =Watchlist!G3 -> -2.02 | F8: =Watchlist!F3 -> 23.2406 | G8: =Watchlist!E3 -> 1.103 | H8: =Watchlist!J3 -> 2758175635760 | I8: =Watchlist!C3 -> 555.45 | J8: =Watchlist!D3 -> 344.79 | K8: {=(_FV(Watchlist!A3,"Price")-Watchlist!D3)/(Watchlist!C3-Watchlist!D3)} -> 0.12650717 | L8: =IF(COUNTIF(Ledger[Ticker],B8)>0,"⚠ IN PORTFOLIO","✔ UNIQUE") -> ✔ UNIQUE | M8: =B8 -> MSFT | N8: =K8 -> 0.12650717
B9: =Watchlist!B4 -> BABA | C9: =Watchlist!K4 -> Software & IT Services | D9: {=_FV(Watchlist!A4,"Price")} -> 122.68 | E9: =Watchlist!G4 -> 0.63 | F9: =Watchlist!F4 -> 16.6848 | G9: =Watchlist!E4 -> 0.4949 | H9: =Watchlist!J4 -> 292887826840 | I9: =Watchlist!C4 -> 192.67 | J9: =Watchlist!D4 -> 94.9742 | K9: {=(_FV(Watchlist!A4,"Price")-Watchlist!D4)/(Watchlist!C4-Watchlist!D4)} -> 0.28359254 | L9: =IF(COUNTIF(Ledger[Ticker],B9)>0,"⚠ IN PORTFOLIO","✔ UNIQUE") -> ✔ UNIQUE | M9: =B9 -> BABA | N9: =K9 -> 0.28359254
B10: =Watchlist!B5 -> DELL | C10: =Watchlist!K5 -> Computers, Phones & Household Electronics | D10: {=_FV(Watchlist!A5,"Price")} -> 173.15 | E10: =Watchlist!G5 -> -1.22 | F10: =Watchlist!F5 -> 19.8578 | G10: =Watchlist!E5 -> 0.8573 | H10: =Watchlist!J5 -> 111811352775 | I10: =Watchlist!C5 -> 186.39 | J10: =Watchlist!D5 -> 66.245 | K10: {=(_FV(Watchlist!A5,"Price")-Watchlist!D5)/(Watchlist!C5-Watchlist!D5)} -> 0.88979983 | L10: =IF(COUNTIF(Ledger[Ticker],B10)>0,"⚠ IN PORTFOLIO","✔ UNIQUE") -> ✔ UNIQUE | M10: =B10 -> DELL | N10: =K10 -> 0.88979983
B11: =Watchlist!B6 -> GS | C11: =Watchlist!K6 -> Investment Banking & Investment Services | D11: {=_FV(Watchlist!A6,"Price")} -> 865.7427 | E11: =Watchlist!G6 -> 2.7027 | F11: =Watchlist!F6 -> 16.8759 | G11: =Watchlist!E6 -> 1.3147 | H11: =Watchlist!J6 -> 255388815469 | I11: =Watchlist!C6 -> 984.7 | J11: =Watchlist!D6 -> 439.38 | K11: {=(_FV(Watchlist!A6,"Price")-Watchlist!D6)/(Watchlist!C6-Watchlist!D6)} -> 0.78185781 | L11: =IF(COUNTIF(Ledger[Ticker],B11)>0,"⚠ IN PORTFOLIO","✔ UNIQUE") -> ✔ UNIQUE | M11: =B11 -> GS | N11: =K11 -> 0.78185781
B12: =Watchlist!B7 -> XOM | C12: =Watchlist!K7 -> Oil & Gas | D12: {=_FV(Watchlist!A7,"Price")} -> 161.03 | E12: =Watchlist!G7 -> 0.34 | F12: =Watchlist!F7 -> 24.1045 | G12: =Watchlist!E7 -> 0.2919 | H12: =Watchlist!J7 -> 670974006920 | I12: =Watchlist!C7 -> 176.41 | J12: =Watchlist!D7 -> 97.8 | K12: {=(_FV(Watchlist!A7,"Price")-Watchlist!D7)/(Watchlist!C7-Watchlist!D7)} -> 0.80435059 | L12: =IF(COUNTIF(Ledger[Ticker],B12)>0,"⚠ IN PORTFOLIO","✔ UNIQUE") -> ✔ UNIQUE | M12: =B12 -> XOM | N12: =K12 -> 0.80435059
B13: =Watchlist!B8 -> GM | C13: =Watchlist!K8 -> Automobiles & Auto Parts | D13: {=_FV(Watchlist!A8,"Price")} -> 73.16 | E13: =Watchlist!G8 -> 0.62 | F13: =Watchlist!F8 -> 22.3854 | G13: =Watchlist!E8 -> 1.3733 | H13: =Watchlist!J8 -> 66134284248 | I13: =Watchlist!C8 -> 87.62 | J13: =Watchlist!D8 -> 41.6 | K13: {=(_FV(Watchlist!A8,"Price")-Watchlist!D8)/(Watchlist!C8-Watchlist!D8)} -> 0.68578879 | L13: =IF(COUNTIF(Ledger[Ticker],B13)>0,"⚠ IN PORTFOLIO","✔ UNIQUE") -> ✔ UNIQUE | M13: =B13 -> GM | N13: =K13 -> 0.68578879
B14: =Watchlist!B9 -> BAC | C14: =Watchlist!K9 -> Banking Services | D14: {=_FV(Watchlist!A9,"Price")} -> 49.835 | E14: =Watchlist!G9 -> 0.455 | F14: =Watchlist!F9 -> 13.1741 | G14: =Watchlist!E9 -> 1.2422 | H14: =Watchlist!J9 -> 356106408015 | I14: =Watchlist!C9 -> 57.55 | J14: =Watchlist!D9 -> 33.065 | K14: {=(_FV(Watchlist!A9,"Price")-Watchlist!D9)/(Watchlist!C9-Watchlist!D9)} -> 0.68490913 | L14: =IF(COUNTIF(Ledger[Ticker],B14)>0,"⚠ IN PORTFOLIO","✔ UNIQUE") -> ✔ UNIQUE | M14: =B14 -> BAC | N14: =K14 -> 0.68490913
B15: =Watchlist!B10 -> LMT | C15: =Watchlist!K10 -> Aerospace & Defense | D15: {=_FV(Watchlist!A10,"Price")} -> 624.5687 | E15: =Watchlist!G10 -> 1.7787 | F15: =Watchlist!F10 -> 29.0685 | G15: =Watchlist!E10 -> 0.2367 | H15: =Watchlist!J10 -> 143939414196 | I15: =Watchlist!C10 -> 692 | J15: =Watchlist!D10 -> 410.11 | K15: {=(_FV(Watchlist!A10,"Price")-Watchlist!D10)/(Watchlist!C10-Watchlist!D10)} -> 0.76078861 | L15: =IF(COUNTIF(Ledger[Ticker],B15)>0,"⚠ IN PORTFOLIO","✔ UNIQUE") -> ✔ UNIQUE | M15: =B15 -> LMT | N15: =K15 -> 0.76078861
B16: =Watchlist!B11 -> COST | C16: =Watchlist!K11 -> Diversified Retail | D16: {=_FV(Watchlist!A11,"Price")} -> 1016.87 | E16: =Watchlist!G11 -> 1.91 | F16: =Watchlist!F11 -> 54.4707 | G16: =Watchlist!E11 -> 0.989 | H16: =Watchlist!J11 -> 451136917675 | I16: =Watchlist!C11 -> 1067.08 | J16: =Watchlist!D11 -> 844.06 | K16: {=(_FV(Watchlist!A11,"Price")-Watchlist!D11)/(Watchlist!C11-Watchlist!D11)} -> 0.77486324 | L16: =IF(COUNTIF(Ledger[Ticker],B16)>0,"⚠ IN PORTFOLIO","✔ UNIQUE") -> ✔ UNIQUE | M16: =B16 -> COST | N16: =K16 -> 0.77486324
