Workbook

Sheet README
A1: 📊 STOCK PORTFOLIO TRACKER & ANALYTICS ENGINE
A2: A comprehensive Excel-based financial analytics platform for multi-asset portfolio management
A4: 🎯 PROJECT OVERVIEW
A5: Objective | B5: Build a real-world stock portfolio tracking system with advanced analytics, risk metrics, and sector diversification analysis — designed to demonstrate proficiency in financial modelling, data transformation, and dashboard design.
A6: Scope | B6: 16 stocks across 10 GICS industries, tracked over 7 years (2019-2025) with Buy/Sell transactions, live market data integration via Excel Stocks data type, and automated P&L calculations.
A7: Investment Strategy | B7: $10,000 annual investment allocated with 35% Technology, 20% Finance, 45% Other sectors. 70/30 Buy/Sell split per stock with systematic rebalancing.
A8: Data Sources | B8: Excel Linked Data Types (Stocks), STOCKHISTORY function for price series, historical closing prices from Nasdaq/Yahoo Finance for transaction pricing.
A10: WORKBOOK STRUCTURE
A11: Sheet Name | B11: Description
A12: Dashboard | B12: Main portfolio view with live stock prices, market values, daily P&L, unrealised gains/losses, sparkline charts, and KPI summary cards.
A13: Analytics | B13: Advanced metrics: per-stock returns and IRR, realised P&L, sector concentration (HHI Index), risk assessment, allocation charts.
A14: Ledger | B14: Transaction history: 112 records, 16 stocks, 7 years. Date, Stock, Type, Price, Units, Transaction Amount.
A15: Watchlist | B15: Competitor analysis: 10 rival stocks with live data, 52-week ranges, beta, P/E, market cap.
A16: Risk Analytics | B16: CAPM analysis, parametric and historical VaR, realised volatility, drawdown and tracking error from 12 months of daily prices, beta decomposition, CML positioning, individual stock risk attribution.
A17: WL Dashboard | B17: Watchlist scoring model: multi-factor evaluation (P/E, Beta, 52-week range, margin of safety) with composite rankings and entry-point signals.
A18: Validation | B18: Automated integrity tests: weight summation, P&L identity, net-of-sales units, HHI consistency, risk metric reasonableness and cross-sheet checks, real-time pass/fail.
A19: Price History | B19: Price history data feeding Dashboard sparkline trend visualizations.
A20: Stock Sheets | B20: Individual stock deep-dives with STOCKHISTORY price series and charts.
A21: Portfolio Series | B21: 12-month back-cast of the current holdings: daily value, returns, volatility, drawdown, VaR and tracking error vs SPY.
A22: KEY FORMULAS & TECHNIQUES
A23: Technique | B23: Implementation
A24: Dynamic Arrays | B24: SORT, UNIQUE, FILTER, SORTBY with spill ranges for automatic data propagation
A25: Linked Data Types | B25: Excel Stocks data type with dot notation for real-time market data integration
A26: STOCKHISTORY | B26: Historical price series retrieval for sparklines and stock analysis sheets
A27: SUMIF / COUNTIF | B27: Cross-sheet aggregation for transaction totals and sector-level rollups from Ledger
A28: INDEX / MATCH | B28: Best and worst performer identification with dynamic lookups across spill ranges
A29: IRR (XIRR) | B29: Money-weighted annual return over the dated purchase and sale cash flows, with today's market value as the final flow
A30: HHI Index | B30: Sum of squared sector weights to quantify portfolio concentration risk
A31: Conditional Formatting | B31: Automated color coding for negative/positive values with emoji risk indicators
A32: Allocation Model | B32: Weighted allocation with sector caps (Tech max 35%) and systematic Buy/Sell rules
A34: SKILLS DEMONSTRATED
A35: Category | B35: Skills
A36: Financial Modelling | B36: Portfolio construction, P&L tracking, CAGR analysis, risk-adjusted metrics, sector allocation
A37: Data Engineering | B37: Dynamic arrays, linked data types, structured references, cross-sheet data pipelines
A38: Risk Analysis | B38: HHI concentration index, 12-month drawdown and volatility, position sizing, diversification metrics
A39: Dashboard Design | B39: KPI cards, conditional formatting, sparklines, interactive charts, professional color themes
A40: Data Visualisation | B40: Pie charts, bar charts, sparklines, color-coded tables, trend analysis
A41: Domain Knowledge | B41: GICS sector classification, stock market mechanics, Buy/Sell transaction modelling
A43: HOW TO USE
A44: 1. Enable Data Types | B44: Ensure Excel is connected to the internet. The Stocks linked data types in the Ledger and Dashboard require a Microsoft 365 subscription.
...

Sheet Validation
A1: PORTFOLIO VALIDATION TESTS
A2: Automated integrity checks · Real-time validation
A4: DATA INTEGRITY CHECKS
A5: Test | B5: Expected | C5: Actual | D5: Status | E5: Notes
A6: Portfolio weights sum to 100% | B6: 1 | C6: =SUM(Dashboard!L7:L22) -> 1 | D6: =IF(ABS(C6-1)<0.001,"✅ PASS","❌ FAIL") -> ✅ PASS | E6: Sum of all portfolio weights must equal 100%
A7: Total MV = Sum of holdings MV | B7: =Dashboard!B3 -> 211334.92 | C7: =SUM(Dashboard!F7:F22) -> 211334.92 | D7: =IF(ABS(B7-C7)<1,"✅ PASS","❌ FAIL") -> ✅ PASS | E7: Portfolio value KPI matches sum of individual market values
A8: Cost basis consistency | B8: =Dashboard!D3 -> 42915.801 | C8: =SUM(Dashboard!N7:N22) -> 42915.801 | D8: =IF(ABS(B8-C8)<1,"✅ PASS","❌ FAIL") -> ✅ PASS | E8: Portfolio cost basis KPI matches sum of per-stock cost bases
A9: P&L identity: MV - CB = Unrealised P&L | B9: =Dashboard!E3 -> 168419.12 | C9: =Dashboard!B3-Dashboard!D3 -> 168419.12 | D9: =IF(ABS(B9-C9)<1,"✅ PASS","❌ FAIL") -> ✅ PASS | E9: Accounting identity: Unrealised P&L = Market Value − Cost Basis
A10: Unique stock count matches | B10: 16 | C10: =COUNTA(Dashboard!B7:B22) -> 16 | D10: =IF(B10=C10,"✅ PASS","❌ FAIL") -> ✅ PASS | E10: Dashboard shows all 16 unique stocks from Ledger
A11: Sector allocation weights sum to 100% | B11: 1 | C11: =SUM(Dashboard!D30:D39) -> 1 | D11: =IF(ABS(C11-1)<0.001,"✅ PASS","❌ FAIL") -> ✅ PASS | E11: Sector allocation must sum to 100%
A12: HHI consistency (Dashboard vs Analytics) | B12: =Dashboard!J3 -> 0.40936259 | C12: =Dashboard!K25 -> 0.40936259 | D12: =IF(ABS(B12-C12)<0.001,"✅ PASS","❌ FAIL") -> ✅ PASS | E12: HHI Index must be identical between KPI strip and bottom KPIs
A13: HHI = sum of sector squared weights | B13: =Dashboard!J3 -> 0.40936259 | C13: =SUM(Dashboard!E30:E39) -> 0.40936259 | D13: =IF(ABS(B13-C13)<0.001,"✅ PASS","❌ FAIL") -> ✅ PASS | E13: HHI = Σ(wi²) from sector allocation table
A14: Win rate consistency | B14: =Dashboard!O3 -> 0.9375 | C14: =COUNTIF(Dashboard!I7:I22,">0")/COUNTA(Dashboard!I7:I22) -> 0.9375 | D14: =IF(ABS(B14-C14)<0.001,"✅ PASS","❌ FAIL") -> ✅ PASS | E14: Win rate KPI matches manual count of profitable holdings
A15: Rebalancing equal weights = 1/N | B15: =1/16 -> 0.0625 | C15: =Dashboard!I30 -> 0.0625 | D15: =IF(ABS(B15-C15)<0.001,"✅ PASS","❌ FAIL") -> ✅ PASS | E15: Equal weight target = 1/N = 6.25% for 16 stocks
A16: Sector MV = sum of stock MVs per sector | B16: =Dashboard!B3 -> 211334.92 | C16: =SUM(Dashboard!C30:C39) -> 211334.92 | D16: =IF(ABS(B16-C16)<1,"✅ PASS","❌ FAIL") -> ✅ PASS | E16: Sum of sector market values equals total portfolio market value
A17: Units = bought − sold (ledger) | B17: =SUMIFS(Ledger[Units],Ledger[Transaction Type],"Buy")-SUMIFS(Ledger[Units],Ledger[Transaction Type],"Sell") -> 1008.21 | C17: =SUM(Dashboard!D7:D22) -> 1008.21 | D17: =IF(ABS(B17-C17)<0.01,"✅ PASS","❌ FAIL") -> ✅ PASS | E17: Held units must equal units bought minus units sold
A18: RISK METRIC CHECKS
A19: Test | B19: Expected Range | C19: Actual | D19: Status | E19: Framework
A20: Sharpe Ratio in valid range | B20: -3.0 to 5.0 | C20: =Dashboard!N3 -> 1.2122662 | D20: =IF(AND(C20>=-3,C20<=5),"✅ PASS","⚠️ CHECK") -> ✅ PASS | E20: Sharpe = (Rp−Rf)/σp; typical range -3 to 5 for diversified portfolios
A21: Portfolio Beta reasonable | B21: 0.3 to 2.5 | C21: =Dashboard!R3 -> 1.8150362 | D21: =IF(AND(C21>=0.3,C21<=2.5),"✅ PASS","⚠️ CHECK") -> ✅ PASS | E21: βp = Σ(wi×βi); 0.3-2.5 typical for equity-only portfolio
A22: Treynor Ratio valid | B22: -0.5 to 1.0 | C22: =Dashboard!S3 -> 0.17343393 | D22: =IF(AND(C22>=-0.5,C22<=1),"✅ PASS","⚠️ CHECK") -> ✅ PASS | E22: Treynor = (Rp−Rf)/βp; measures excess return per unit systematic risk
A23: Max Drawdown ≤ 0 | B23: ≤ 0% | C23: =Dashboard!Q3 -> -0.14841703 | D23: =IF(C23<=0,"✅ PASS","❌ FAIL") -> ✅ PASS | E23: 12-month peak-to-trough decline of the current holdings; must be ≤ 0
A24: Calmar Ratio positive (if CAGR positive) | B24: > 0 | C24: =Dashboard!R25 -> 2.4073308 | D24: =IF(C24>0,"✅ PASS","⚠️ CHECK") -> ✅ PASS | E24: Calmar = 12m return / |12m max drawdown|
A25: No negative holdings | B25: ≥ 0 | C25: =MIN(Dashboard!D7:D22) -> 2.55 | D25: =IF(C25>=0,"✅ PASS","❌ FAIL") -> ✅ PASS | E25: Every holding's net units must be zero or positive
A26: SUMMARY
A27: Tests Passed | B27: Tests Failed | C27: Tests Warning | D27: Overall Score
A28: =COUNTIF(D6:D17,"✅*")+COUNTIF(D20:D25,"✅*")+COUNTIF(D32:D39,"✅*") -> 26 | B28: {=COUNTIF(D6:D17,"❌*")+COUNTIF(D20:D25,"❌*")+COUNTIF(D32:D39,"❌*")+SUMPRODUCT(--ISERROR(D6:D17))+SUMPRODUCT(--ISERROR(D20:D25))+SUMPRODUCT(--ISERROR(D32:D39))} -> 0 | C28: =COUNTIF(D6:D17,"⚠️*")+COUNTIF(D20:D25,"⚠️*")+COUNTIF(D32:D39,"⚠️*") -> 0 | D28: =IF(B28=0,IF(C28=0,"✅ ALL PASS","⚠️ WARNINGS"),"❌ FAILURES") -> ✅ ALL PASS
A30: CROSS-SHEET CONSISTENCY CHECKS
A31: Test | B31: Sheet A | C31: Sheet B | D31: Status | E31: Detail
A32: CAGR: Dashboard ↔ Analytics | B32: =Dashboard!G3 -> 0.32227901 | C32: =Analytics!E6 -> 0.32227901 | D32: =IF(ABS(B32-C32)<0.0001,"✅ PASS","❌ FAIL") -> ✅ PASS | E32: Portfolio CAGR must match across Dashboard and Analytics
A33: Beta: Dashboard ↔ Risk Analytics | B33: =Dashboard!R3 -> 1.8150362 | C33: ='Risk Analytics'!C9 -> 1.8150362 | D33: =IF(ABS(B33-C33)<0.001,"✅ PASS","❌ FAIL") -> ✅ PASS | E33: Weighted portfolio beta must match between Dashboard KPI and Risk Analytics
A34: Sharpe: Dashboard ↔ Risk Analytics | B34: =Dashboard!N3 -> 1.2122662 | C34: ='Risk Analytics'!C18 -> 1.2122662 | D34: =IF(ABS(B34-C34)<0.001,"✅ PASS","❌ FAIL") -> ✅ PASS | E34: Sharpe Ratio must match between Dashboard KPI and Risk Analytics
A35: Treynor: Dashboard ↔ Risk Analytics | B35: =Dashboard!S3 -> 0.17343393 | C35: ='Risk Analytics'!C15 -> 0.17343393 | D35: =IF(ABS(B35-C35)<0.0001,"✅ PASS","❌ FAIL") -> ✅ PASS | E35: Treynor Ratio must match between Dashboard and Risk Analytics
A36: CAPM: E(Rp) = Rf + βp(Rm-Rf) | B36: ='Risk Analytics'!C10 -> 0.14686458 | C36: ='Risk Analytics'!C6+'Risk Analytics'!C9*('Risk Analytics'!C7-'Risk Analytics'!C6) -> 0.14686458 | D36: =IF(ABS(B36-C36)<0.0001,"✅ PASS","❌ FAIL") -> ✅ PASS | E36: CAPM expected return formula: Rf + βp × ERP must be internally consistent
A37: Jensen's α = Rp(12m) − E(Rp) | B37: ='Risk Analytics'!C11 -> 0.21042429 | C37: ='Portfolio Series'!B13-'Risk Analytics'!C10 -> 0.21042429 | D37: =IF(ABS(B37-C37)<0.0001,"✅ PASS","❌ FAIL") -> ✅ PASS | E37: Alpha = Actual CAGR minus CAPM expected return
A38: Risk decomp weights sum to 100% | B38: 1 | C38: ='Risk Analytics'!C55 -> 1 | D38: =IF(ABS(C38-1)<0.001,"✅ PASS","❌ FAIL") -> ✅ PASS | E38: Stock weights in risk decomposition table must sum to 100%
A39: Total gain = realised + unrealised | B39: =Dashboard!B3+SUMIFS(Ledger[Transaction Amount],Ledger[Transaction Type],"Sell")-SUMIFS(Ledger[Transaction Amount],Ledger[Transaction Type],"Buy") -> 183362.84 | C39: =Dashboard!E3+Dashboard!P25 -> 183362.84 | D39: =IF(ABS(B39-C39)<1,"✅ PASS","❌ FAIL") -> ✅ PASS | E39: Market value + sale proceeds − purchases = realised + unrealised P&L

Sheet Dashboard
U1: Ticker | V1: Return % | W1: Weight % | X1: Gain/Loss | Y1: Ann. Return | Z1: Ticker | AA1: Gain/Loss | AB1: Ticker | AC1: Ann. Return | AD1: Ticker | AE1: Weight
B2: PORTFOLIO VALUE | D2: COST BASIS | E2: UNREALISED P&L | F2: TOTAL RETURN | G2: ANN. RETURN (IRR) | H2: BEST STOCK | I2: WORST STOCK | J2: HHI INDEX | M2: DAILY P&L | N2: SHARPE RATIO | O2: WIN RATE | P2: AVG RETURN | Q2: MAX DRAWDOWN (12M) | R2: PORT. BETA | S2: TREYNOR | U2: =M7 -> AMD | V2: =K7 -> 10.32239 | W2: =L7 -> 0.17183225 | X2: =I7 -> 33106.867 | Y2: =Q7 -> 0.55674189 | Z2: =M7 -> AMD | AA2: =I7 -> 33106.867 | AB2: =M7 -> AMD | AC2: =Q7 -> 0.55674189 | AD2: =M7 -> AMD | AE2: =L7 -> 0.17183225
B3: =SUM(_xlfn.ANCHORARRAY(F7)) -> 211334.92 | D3: =SUM(F7:F22)-SUM(I7:I22) -> 42915.801 | E3: =SUM(I7:I22) -> 168419.12 | F3: =(B3+SUMIFS(Ledger[Transaction Amount],Ledger[Transaction Type],"Sell")-SUMIFS(Ledger[Transaction Amount],Ledger[Transaction Type],"Buy"))/SUMIFS(Ledger[Transaction Amount],Ledger[Transaction Type],"Buy") -> 2.291699 | G3: {=_xlfn.LET(_xlpm.v,_xlfn.VSTACK(IF(Ledger[Transaction Type]="Buy",-1,1)*Ledger[Transaction Amount],B3),_xlpm.d,_xlfn.VSTACK(Ledger[Date],TODAY()),_xlpm.r,XIRR(_xlfn.SORTBY(_xlpm.v,_xlpm.d),_xlfn._xlws.SORT(_xlpm.d),IF(SUM(_xlpm.v)<0,-0.1,0.1)),IF(ABS(_xlpm.r)<0.0000001,NA(),_xlpm.r))} -> 0.32227901 | H3: ="▲ "&INDEX(Ledger[Ticker],MATCH(INDEX(_xlfn.ANCHORARRAY(B7),MATCH(MAX(I7:I22),I7:I22,0)),Ledger[Stock],0)) -> ▲ NVDA | I3: ="▼ "&INDEX(Ledger[Ticker],MATCH(INDEX(_xlfn.ANCHORARRAY(B7),MATCH(MIN(I7:I22),I7:I22,0)),Ledger[Stock],0)) -> ▼ BA | J3: {=SUMPRODUCT((SUMIF(_xlfn.ANCHORARRAY(C7),_xlfn.UNIQUE(_xlfn.ANCHORARRAY(C7)),_xlfn.ANCHORARRAY(F7))/SUM(_xlfn.ANCHORARRAY(F7)))^2)} -> 0.40936259 | M3: =SUMPRODUCT(_xlfn.ANCHORARRAY(D7),_xlfn.ANCHORARRAY(G7)) -> -950.529 | N3: ='Risk Analytics'!C18 -> 1.2122662 | O3: =COUNTIF(I7:I22,">0")/COUNTA(I7:I22) -> 0.9375 | P3: =AVERAGE(K7:K22) -> 2.7406333 | Q3: ='Portfolio Series'!B16 -> -0.14841703 | R3: ='Risk Analytics'!C9 -> 1.8150362 | S3: ='Risk Analytics'!C15 -> 0.17343393 | U3: =M8 -> GOOG | V3: =K8 -> 2.5942224 | W3: =L8 -> 0.053377178 | X3: =I8 -> 8141.9631 | Y3: =Q8 -> 0.30156799 | Z3: =M8 -> GOOG | AA3: =I8 -> 8141.9631 | AB3: =M8 -> GOOG | AC3: =Q8 -> 0.30156799 | AD3: =M8 -> GOOG | AE3: =L8 -> 0.053377178
U4: =M9 -> AMZN | V4: =K9 -> 1.0848749 | W4: =L9 -> 0.024424575 | X4: =I9 -> 2685.9501 | Y4: =Q9 -> 0.19556205 | Z4: =M9 -> AMZN | AA4: =I9 -> 2685.9501 | AB4: =M9 -> AMZN | AC4: =Q9 -> 0.19556205 | AD4: =M9 -> AMZN | AE4: =L9 -> 0.024424575
B5: CURRENT HOLDINGS · 16 STOCKS · 10 INDUSTRIES | M5: FINANCIAL METRICS · PER-STOCK ANALYTICS · RISK ASSESSMENT | U5: =M10 -> AAPL | V5: =K10 -> 2.1898434 | W5: =L10 -> 0.047204845 | X5: =I10 -> 6848.5957 | Y5: =Q10 -> 0.28999216 | Z5: =M10 -> AAPL | AA5: =I10 -> 6848.5957 | AB5: =M10 -> AAPL | AC5: =Q10 -> 0.28999216 | AD5: =M10 -> AAPL | AE5: =L10 -> 0.047204845
B6: Stock(Exchange: Ticker) | C6: Industry | D6: Units | E6: Current Price | F6: Market Value | G6: Today's Change | I6: Gain/(Loss) | J6: Last 12 Months | K6: Return % | L6: Weight % | M6: Stock | N6: Cost Basis | O6: Avg Buy Price | P6: Price/Cost | Q6: Ann. Return (IRR) | R6: Risk Score | S6: Signal | U6: =M11 -> BLK | V6: =K11 -> 0.64601445 | W6: =L11 -> 0.023367944 | X6: =I11 -> 1938.2079 | Y6: =Q11 -> 0.13977041 | Z6: =M11 -> BLK | AA6: =I11 -> 1938.2079 | AB6: =M11 -> BLK | AC6: =Q11 -> 0.13977041 | AD6: =M11 -> BLK | AE6: =L11 -> 0.023367944
B7: {=_xlfn._xlws.SORT(_xlfn.UNIQUE(Ledger[Stock],FALSE,FALSE))} -> #VALUE! | C7: {=_FV(_xlfn.ANCHORARRAY(B7),"Industry")} -> Semiconductors & Semiconductor Equipment | D7: {=SUMIFS(Ledger[Units],Ledger[Stock],_xlfn.ANCHORARRAY(B7),Ledger[Transaction Type],"Buy")-SUMIFS(Ledger[Units],Ledger[Stock],_xlfn.ANCHORARRAY(B7),Ledger[Transaction Type],"Sell")} -> 59.74 | E7: {=_FV(_xlfn.ANCHORARRAY(B7),"Price")} -> 607.87 | F7: {=_xlfn.ANCHORARRAY(D7)*_xlfn.ANCHORARRAY(E7)} -> 36314.154 | G7: {=_xlfn.ANCHORARRAY(E7)-_FV(_xlfn.ANCHORARRAY(B7),"Previous close",TRUE)} -> -22.76 | H7: {=_xlfn.ANCHORARRAY(G7)/(_xlfn.ANCHORARRAY(E7)-_xlfn.ANCHORARRAY(G7))} -> -0.036090893 | I7: {=_xlfn.ANCHORARRAY(F7)-_xlfn.ANCHORARRAY(D7)*SUMIFS(Ledger[Transaction Amount],Ledger[Stock],_xlfn.ANCHORARRAY(B7),Ledger[Transaction Type],"Buy")/SUMIFS(Ledger[Units],Ledger[Stock],_xlfn.ANCHORARRAY(B7),Ledger[Transaction Type],"Buy")} -> 33106.867 | K7: =IF((F7-I7)=0,0,I7/(F7-I7)) -> 10.32239 | L7: =F7/SUM(F7:F22) -> 0.17183225 | M7: =INDEX(Ledger[Ticker],MATCH(B7,Ledger[Stock],0)) -> AMD | N7: =F7-I7 -> 3207.287 | O7: =N7/D7 -> 53.68743 | P7: =E7/O7 -> 11.32239 | Q7: {=_xlfn.LET(_xlpm.m,Ledger[Stock]=B7,_xlpm.v,_xlfn.VSTACK(_xlfn._xlws.FILTER(IF(Ledger[Transaction Type]="Buy",-1,1)*Ledger[Transaction Amount],_xlpm.m),F7),_xlpm.d,_xlfn.VSTACK(_xlfn._xlws.FILTER(Ledger[Date],_xlpm.m),TODAY()),_xlpm.r,XIRR(_xlfn.SORTBY(_xlpm.v,_xlpm.d),_xlfn._xlws.SORT(_xlpm.d),IF(SUM(_xlpm.v)<0,-0.1,0.1)),IF(ABS(_xlpm.r)<0.0000001,NA(),_xlpm.r))} -> 0.55674189 | R7: =IF(OR(K7<0,Q7<0,L7>0.2),"HIGH",IF(OR(K7<0.5,Q7<0.05,L7>0.15),"MEDIUM","LOW")) -> MEDIUM | S7: =IF(AND(Q7>0.1,K7>1,P7>1.5,R7="LOW"),"▲ STRONG",IF(OR(K7<0,Q7<0),"▼ REVIEW","▶ HOLD")) -> ▶ HOLD | U7: =M12 -> CVX | V7: =K12 -> 0.59446216 | W7: =L12 -> 0.0177236 | X7: =I12 -> 1396.4751 | Y7: =Q12 -> 0.077858725 | Z7: =M12 -> CVX | AA7: =I12 -> 1396.4751 | AB7: =M12 -> CVX | AC7: =Q12 -> 0.077858725 | AD7: =M12 -> CVX | AE7: =L12 -> 0.0177236
B8: #VALUE! | C8: Software & IT Services | D8: 33.26 | E8: 339.16 | F8: 11280.462 | G8: -1.92 | H8: -0.0056291779 | I8: 8141.9631 | K8: =IF((F8-I8)=0,0,I8/(F8-I8)) -> 2.5942224 | L8: =F8/SUM(F7:F22) -> 0.053377178 | M8: =INDEX(Ledger[Ticker],MATCH(B8,Ledger[Stock],0)) -> GOOG | N8: =F8-I8 -> 3138.4985 | O8: =N8/D8 -> 94.362552 | P8: =E8/O8 -> 3.5942224 | Q8: {=_xlfn.LET(_xlpm.m,Ledger[Stock]=B8,_xlpm.v,_xlfn.VSTACK(_xlfn._xlws.FILTER(IF(Ledger[Transaction Type]="Buy",-1,1)*Ledger[Transaction Amount],_xlpm.m),F8),_xlpm.d,_xlfn.VSTACK(_xlfn._xlws.FILTER(Ledger[Date],_xlpm.m),TODAY()),_xlpm.r,XIRR(_xlfn.SORTBY(_xlpm.v,_xlpm.d),_xlfn._xlws.SORT(_xlpm.d),IF(SUM(_xlpm.v)<0,-0.1,0.1)),IF(ABS(_xlpm.r)<0.0000001,NA(),_xlpm.r))} -> 0.30156799 | R8: =IF(OR(K8<0,Q8<0,L8>0.2),"HIGH",IF(OR(K8<0.5,Q8<0.05,L8>0.15),"MEDIUM","LOW")) -> LOW | S8: =IF(AND(Q8>0.1,K8>1,P8>1.5,R8="LOW"),"▲ STRONG",IF(OR(K8<0,Q8<0),"▼ REVIEW","▶ HOLD")) -> ▲ STRONG | U8: =M13 -> C | V8: =K13 -> 1.402836 | W8: =L13 -> 0.027357425 | X8: =I13 -> 3375.4312 | Y8: =Q13 -> 0.17262424 | Z8: =M13 -> C | AA8: =I13 -> 3375.4312 | AB8: =M13 -> C | AC8: =Q13 -> 0.17262424 | AD8: =M13 -> C | AE8: =L13 -> 0.027357425
B9: #VALUE! | C9: Diversified Retail | D9: 20.97 | E9: 246.15 | F9: 5161.7655 | G9: -3.52 | H9: -0.01409861 | I9: 2685.9501 | K9: =IF((F9-I9)=0,0,I9/(F9-I9)) -> 1.0848749 | L9: =F9/SUM(F7:F22) -> 0.024424575 | M9: =INDEX(Ledger[Ticker],MATCH(B9,Ledger[Stock],0)) -> AMZN | N9: =F9-I9 -> 2475.8154 | O9: =N9/D9 -> 118.06464 | P9: =E9/O9 -> 2.0848749 | Q9: {=_xlfn.LET(_xlpm.m,Ledger[Stock]=B9,_xlpm.v,_xlfn.VSTACK(_xlfn._xlws.FILTER(IF(Ledger[Transaction Type]="Buy",-1,1)*Ledger[Transaction Amount],_xlpm.m),F9),_xlpm.d,_xlfn.VSTACK(_xlfn._xlws.FILTER(Ledger[Date],_xlpm.m),TODAY()),_xlpm.r,XIRR(_xlfn.SORTBY(_xlpm.v,_xlpm.d),_xlfn._xlws.SORT(_xlpm.d),IF(SUM(_xlpm.v)<0,-0.1,0.1)),IF(ABS(_xlpm.r)<0.0000001,NA(),_xlpm.r))} -> 0.19556205 | R9: =IF(OR(K9<0,Q9<0,L9>0.2),"HIGH",IF(OR(K9<0.5,Q9<0.05,L9>0.15),"MEDIUM","LOW")) -> LOW | S9: =IF(AND(Q9>0.1,K9>1,P9>1.5,R9="LOW"),"▲ STRONG",IF(OR(K9<0,Q9<0),"▼ REVIEW","▶ HOLD")) -> ▲ STRONG | U9: =M14 -> F | V9: =K14 -> 0.1851305 | W9: =L14 -> 0.010201707 | X9: =I14 -> 336.78746 | Y9: =Q14 -> 0.032022062 | Z9: =M14 -> F | AA9: =I14 -> 336.78746 | AB9: =M14 -> F | AC9: =Q14 -> 0.032022062 | AD9: =M14 -> F | AE9: =L14 -> 0.010201707
B10: #VALUE! | C10: Computers, Phones & Household Electronics | D10: 29.48 | E10: 338.4 | F10: 9976.032 | G10: -2.67 | H10: -0.007828305 | I10: 6848.5957 | K10: =IF((F10-I10)=0,0,I10/(F10-I10)) -> 2.1898434 | L10: =F10/SUM(F7:F22) -> 0.047204845 | M10: =INDEX(Ledger[Ticker],MATCH(B10,Ledger[Stock],0)) -> AAPL | N10: =F10-I10 -> 3127.4363 | O10: =N10/D10 -> 106.08671 | P10: =E10/O10 -> 3.1898434 | Q10: {=_xlfn.LET(_xlpm.m,Ledger[Stock]=B10,_xlpm.v,_xlfn.VSTACK(_xlfn._xlws.FILTER(IF(Ledger[Transaction Type]="Buy",-1,1)*Ledger[Transaction Amount],_xlpm.m),F10),_xlpm.d,_xlfn.VSTACK(_xlfn._xlws.FILTER(Ledger[Date],_xlpm.m),TODAY()),_xlpm.r,XIRR(_xlfn.SORTBY(_xlpm.v,_xlpm.d),_xlfn._xlws.SORT(_xlpm.d),IF(SUM(_xlpm.v)<0,-0.1,0.1)),IF(ABS(_xlpm.r)<0.0000001,NA(),_xlpm.r))} -> 0.28999216 | R10: =IF(OR(K10<0,Q10<0,L10>0.2),"HIGH",IF(OR(K10<0.5,Q10<0.05,L10>0.15),"MEDIUM","LOW")) -> LOW | S10: =IF(AND(Q10>0.1,K10>1,P10>1.5,R10="LOW"),"▲ STRONG",IF(OR(K10<0,Q10<0),"▼ REVIEW","▶ HOLD")) -> ▲ STRONG | U10: =M15 -> HMC | V10: =K15 -> 0.15869699 | W10: =L15 -> 0.0075684733 | X10: =I15 -> 219.06771 | Y10: =Q15 -> 0.0072583467 | Z10: =M15 -> HMC | AA10: =I15 -> 219.06771 | AB10: =M15 -> HMC | AC10: =Q15 -> 0.0072583467 | AD10: =M15 -> HMC | AE10: =L15 -> 0.0075684733
B11: #VALUE! | C11: Investment Banking & Investment Services | D11: 4.61 | E11: 1071.25 | F11: 4938.4625 | G11: -15.06 | H11: -0.013863446 | I11: 1938.2079 | K11: =IF((F11-I11)=0,0,I11/(F11-I11)) -> 0.64601445 | L11: =F11/SUM(F7:F22) -> 0.023367944 | M11: =INDEX(Ledger[Ticker],MATCH(B11,Ledger[Stock],0)) -> BLK | N11: =F11-I11 -> 3000.2546 | O11: =N11/D11 -> 650.81446 | P11: =E11/O11 -> 1.6460145 | Q11: {=_xlfn.LET(_xlpm.m,Ledger[Stock]=B11,_xlpm.v,_xlfn.VSTACK(_xlfn._xlws.FILTER(IF(Ledger[Transaction Type]="Buy",-1,1)*Ledger[Transaction Amount],_xlpm.m),F11),_xlpm.d,_xlfn.VSTACK(_xlfn._xlws.FILTER(Ledger[Date],_xlpm.m),TODAY()),_xlpm.r,XIRR(_xlfn.SORTBY(_xlpm.v,_xlpm.d),_xlfn._xlws.SORT(_xlpm.d),IF(SUM(_xlpm.v)<0,-0.1,0.1)),IF(ABS(_xlpm.r)<0.0000001,NA(),_xlpm.r))} -> 0.13977041 | R11: =IF(OR(K11<0,Q11<0,L11>0.2),"HIGH",IF(OR(K11<0.5,Q11<0.05,L11>0.15),"MEDIUM","LOW")) -> LOW | S11: =IF(AND(Q11>0.1,K11>1,P11>1.5,R11="LOW"),"▲ STRONG",IF(OR(K11<0,Q11<0),"▼ REVIEW","▶ HOLD")) -> ▶ HOLD | U11: =M16 -> JPM | V11: =K16 -> 1.3670008 | W11: =L16 -> 0.037459956 | X11: =I16 -> 4572.0281 | Y11: =Q16 -> 0.20443895 | Z11: =M16 -> JPM | AA11: =I16 -> 4572.0281 | AB11: =M16 -> JPM | AC11: =Q16 -> 0.20443895 | AD11: =M16 -> JPM | AE11: =L16 -> 0.037459956
B12: #VALUE! | C12: Oil & Gas | D12: 18.15 | E12: 206.37 | F12: 3745.6155 | G12: 1.92 | H12: 0.0093910492 | I12: 1396.4751 | K12: =IF((F12-I12)=0,0,I12/(F12-I12)) -> 0.59446216 | L12: =F12/SUM(F7:F22) -> 0.0177236 | M12: =INDEX(Ledger[Ticker],MATCH(B12,Ledger[Stock],0)) -> CVX | N12: =F12-I12 -> 2349.1404 | O12: =N12/D12 -> 129.42922 | P12: =E12/O12 -> 1.5944622 | Q12: {=_xlfn.LET(_xlpm.m,Ledger[Stock]=B12,_xlpm.v,_xlfn.VSTACK(_xlfn._xlws.FILTER(IF(Ledger[Transaction Type]="Buy",-1,1)*Ledger[Transaction Amount],_xlpm.m),F12),_xlpm.d,_xlfn.VSTACK(_xlfn._xlws.FILTER(Ledger[Date],_xlpm.m),TODAY()),_xlpm.r,XIRR(_xlfn.SORTBY(_xlpm.v,_xlpm.d),_xlfn._xlws.SORT(_xlpm.d),IF(SUM(_xlpm.v)<0,-0.1,0.1)),IF(ABS(_xlpm.r)<0.0000001,NA(),_xlpm.r))} -> 0.077858725 | R12: =IF(OR(K12<0,Q12<0,L12>0.2),"HIGH",IF(OR(K12<0.5,Q12<0.05,L12>0.15),"MEDIUM","LOW")) -> LOW | S12: =IF(AND(Q12>0.1,K12>1,P12>1.5,R12="LOW"),"▲ STRONG",IF(OR(K12<0,Q12<0),"▼ REVIEW","▶ HOLD")) -> ▶ HOLD | U12: =M17 -> META | V12: =K17 -> 2.1443626 | W12: =L17 -> 0.053400202 | X12: =I17 -> 7696.2607 | Y12: =Q17 -> 0.29073516 | Z12: =M17 -> META | AA12: =I17 -> 7696.2607 | AB12: =M17 -> META | AC12: =Q17 -> 0.29073516 | AD12: =M17 -> META | AE12: =L17 -> 0.053400202
B13: #VALUE! | C13: Investment Banking & Investment Services | D13: 44.03 | E13: 131.31 | F13: 5781.5793 | G13: -2.97 | H13: -0.022117962 | I13: 3375.4312 | K13: =IF((F13-I13)=0,0,I13/(F13-I13)) -> 1.402836 | L13: =F13/SUM(F7:F22) -> 0.027357425 | M13: =INDEX(Ledger[Ticker],MATCH(B13,Ledger[Stock],0)) -> C | N13: =F13-I13 -> 2406.1481 | O13: =N13/D13 -> 54.647925 | P13: =E13/O13 -> 2.402836 | Q13: {=_xlfn.LET(_xlpm.m,Ledger[Stock]=B13,_xlpm.v,_xlfn.VSTACK(_xlfn._xlws.FILTER(IF(Ledger[Transaction Type]="Buy",-1,1)*Ledger[Transaction Amount],_xlpm.m),F13),_xlpm.d,_xlfn.VSTACK(_xlfn._xlws.FILTER(Ledger[Date],_xlpm.m),TODAY()),_xlpm.r,XIRR(_xlfn.SORTBY(_xlpm.v,_xlpm.d),_xlfn._xlws.SORT(_xlpm.d),IF(SUM(_xlpm.v)<0,-0.1,0.1)),IF(ABS(_xlpm.r)<0.0000001,NA(),_xlpm.r))} -> 0.17262424 | R13: =IF(OR(K13<0,Q13<0,L13>0.2),"HIGH",IF(OR(K13<0.5,Q13<0.05,L13>0.15),"MEDIUM","LOW")) -> LOW | S13: =IF(AND(Q13>0.1,K13>1,P13>1.5,R13="LOW"),"▲ STRONG",IF(OR(K13<0,Q13<0),"▼ REVIEW","▶ HOLD")) -> ▲ STRONG | U13: =M18 -> NVDA | V13: =K18 -> 18.777934 | W13: =L18 -> 0.45087609 | X13: =I18 -> 90468.075 | Y13: =Q18 -> 0.74484886 | Z13: =M18 -> NVDA | AA13: =I18 -> 90468.075 | AB13: =M18 -> NVDA | AC13: =Q18 -> 0.74484886 | AD13: =M18 -> NVDA | AE13: =L18 -> 0.45087609
B14: #VALUE! | C14: Automobiles & Auto Parts | D14: 174.15 | E14: 12.38 | F14: 2155.977 | G14: -0.33 | H14: -0.025963808 | I14: 336.78746 | K14: =IF((F14-I14)=0,0,I14/(F14-I14)) -> 0.1851305 | L14: =F14/SUM(F7:F22) -> 0.010201707 | M14: =INDEX(Ledger[Ticker],MATCH(B14,Ledger[Stock],0)) -> F | N14: =F14-I14 -> 1819.1895 | O14: =N14/D14 -> 10.446107 | P14: =E14/O14 -> 1.1851305 | Q14: {=_xlfn.LET(_xlpm.m,Ledger[Stock]=B14,_xlpm.v,_xlfn.VSTACK(_xlfn._xlws.FILTER(IF(Ledger[Transaction Type]="Buy",-1,1)*Ledger[Transaction Amount],_xlpm.m),F14),_xlpm.d,_xlfn.VSTACK(_xlfn._xlws.FILTER(Ledger[Date],_xlpm.m),TODAY()),_xlpm.r,XIRR(_xlfn.SORTBY(_xlpm.v,_xlpm.d),_xlfn._xlws.SORT(_xlpm.d),IF(SUM(_xlpm.v)<0,-0.1,0.1)),IF(ABS(_xlpm.r)<0.0000001,NA(),_xlpm.r))} -> 0.032022062 | R14: =IF(OR(K14<0,Q14<0,L14>0.2),"HIGH",IF(OR(K14<0.5,Q14<0.05,L14>0.15),"MEDIUM","LOW")) -> MEDIUM | S14: =IF(AND(Q14>0.1,K14>1,P14>1.5,R14="LOW"),"▲ STRONG",IF(OR(K14<0,Q14<0),"▼ REVIEW","▶ HOLD")) -> ▶ HOLD | U14: =M19 -> 0R2N | V14: =K19 -> 1.0248369 | W14: =L19 -> 0.020764038 | X14: =I19 -> 2220.996 | Y14: =Q19 -> 0.13563055 | Z14: =M19 -> 0R2N | AA14: =I19 -> 2220.996 | AB14: =M19 -> 0R2N | AC14: =Q19 -> 0.13563055 | AD14: =M19 -> 0R2N | AE14: =L19 -> 0.020764038
B15: #VALUE! | C15: Automobiles & Auto Parts | D15: 49.23 | E15: 32.49 | F15: 1599.4827 | G15: -0.44 | H15: -0.013361676 | I15: 219.06771 | K15: =IF((F15-I15)=0,0,I15/(F15-I15)) -> 0.15869699 | L15: =F15/SUM(F7:F22) -> 0.0075684733 | M15: =INDEX(Ledger[Ticker],MATCH(B15,Ledger[Stock],0)) -> HMC | N15: =F15-I15 -> 1380.415 | O15: =N15/D15 -> 28.040118 | P15: =E15/O15 -> 1.158697 | Q15: {=_xlfn.LET(_xlpm.m,Ledger[Stock]=B15,_xlpm.v,_xlfn.VSTACK(_xlfn._xlws.FILTER(IF(Ledger[Transaction Type]="Buy",-1,1)*Ledger[Transaction Amount],_xlpm.m),F15),_xlpm.d,_xlfn.VSTACK(_xlfn._xlws.FILTER(Ledger[Date],_xlpm.m),TODAY()),_xlpm.r,XIRR(_xlfn.SORTBY(_xlpm.v,_xlpm.d),_xlfn._xlws.SORT(_xlpm.d),IF(SUM(_xlpm.v)<0,-0.1,0.1)),IF(ABS(_xlpm.r)<0.0000001,NA(),_xlpm.r))} -> 0.0072583467 | R15: =IF(OR(K15<0,Q15<0,L15>0.2),"HIGH",IF(OR(K15<0.5,Q15<0.05,L15>0.15),"MEDIUM","LOW")) -> MEDIUM | S15: =IF(AND(Q15>0.1,K15>1,P15>1.5,R15="LOW"),"▲ STRONG",IF(OR(K15<0,Q15<0),"▼ REVIEW","▶ HOLD")) -> ▶ HOLD | U15: =M20 -> BA | V15: =K20 -> -0.26147276 | W15: =L20 -> 0.0022248784 | X15: =I20 -> -166.47057 | Y15: =Q20 -> -0.13631248 | Z15: =M20 -> BA | AA15: =I20 -> -166.47057 | AB15: =M20 -> BA | AC15: =Q20 -> -0.13631248 | AD15: =M20 -> BA | AE15: =L20 -> 0.0022248784
B16: #VALUE! | C16: Banking Services | D16: 23.52 | E16: 336.59 | F16: 7916.5968 | G16: -6.47 | H16: -0.018859675 | I16: 4572.0281 | K16: =IF((F16-I16)=0,0,I16/(F16-I16)) -> 1.3670008 | L16: =F16/SUM(F7:F22) -> 0.037459956 | M16: =INDEX(Ledger[Ticker],MATCH(B16,Ledger[Stock],0)) -> JPM | N16: =F16-I16 -> 3344.5687 | O16: =N16/D16 -> 142.20105 | P16: =E16/O16 -> 2.3670008 | Q16: {=_xlfn.LET(_xlpm.m,Ledger[Stock]=B16,_xlpm.v,_xlfn.VSTACK(_xlfn._xlws.FILTER(IF(Ledger[Transaction Type]="Buy",-1,1)*Ledger[Transaction Amount],_xlpm.m),F16),_xlpm.d,_xlfn.VSTACK(_xlfn._xlws.FILTER(Ledger[Date],_xlpm.m),TODAY()),_xlpm.r,XIRR(_xlfn.SORTBY(_xlpm.v,_xlpm.d),_xlfn._xlws.SORT(_xlpm.d),IF(SUM(_xlpm.v)<0,-0.1,0.1)),IF(ABS(_xlpm.r)<0.0000001,NA(),_xlpm.r))} -> 0.20443895 | R16: =IF(OR(K16<0,Q16<0,L16>0.2),"HIGH",IF(OR(K16<0.5,Q16<0.05,L16>0.15),"MEDIUM","LOW")) -> LOW | S16: =IF(AND(Q16>0.1,K16>1,P16>1.5,R16="LOW"),"▲ STRONG",IF(OR(K16<0,Q16<0),"▼ REVIEW","▶ HOLD")) -> ▲ STRONG | U16: =M21 -> TM | V16: =K21 -> 0.22035737 | W16: =L21 -> 0.010059421 | X16: =I21 -> 383.87057 | Y16: =Q21 -> 0.051768842 | Z16: =M21 -> TM | AA16: =I21 -> 383.87057 | AB16: =M21 -> TM | AC16: =Q21 -> 0.051768842 | AD16: =M21 -> TM | AE16: =L21 -> 0.010059421
B17: #VALUE! | C17: Software & IT Services | D17: 15.77 | E17: 715.62 | F17: 11285.327 | G17: -36.04 | H17: -0.04794721 | I17: 7696.2607 | K17: =IF((F17-I17)=0,0,I17/(F17-I17)) -> 2.1443626 | L17: =F17/SUM(F7:F22) -> 0.053400202 | M17: =INDEX(Ledger[Ticker],MATCH(B17,Ledger[Stock],0)) -> META | N17: =F17-I17 -> 3589.0667 | O17: =N17/D17 -> 227.58825 | P17: =E17/O17 -> 3.1443626 | Q17: {=_xlfn.LET(_xlpm.m,Ledger[Stock]=B17,_xlpm.v,_xlfn.VSTACK(_xlfn._xlws.FILTER(IF(Ledger[Transaction Type]="Buy",-1,1)*Ledger[Transaction Amount],_xlpm.m),F17),_xlpm.d,_xlfn.VSTACK(_xlfn._xlws.FILTER(Ledger[Date],_xlpm.m),TODAY()),_xlpm.r,XIRR(_xlfn.SORTBY(_xlpm.v,_xlpm.d),_xlfn._xlws.SORT(_xlpm.d),IF(SUM(_xlpm.v)<0,-0.1,0.1)),IF(ABS(_xlpm.r)<0.0000001,NA(),_xlpm.r))} -> 0.29073516 | R17: =IF(OR(K17<0,Q17<0,L17>0.2),"HIGH",IF(OR(K17<0.5,Q17<0.05,L17>0.15),"MEDIUM","LOW")) -> LOW | S17: =IF(AND(Q17>0.1,K17>1,P17>1.5,R17="LOW"),"▲ STRONG",IF(OR(K17<0,Q17<0),"▼ REVIEW","▶ HOLD")) -> ▲ STRONG | U17: =M22 -> WMT | V17: =K22 -> 1.3986435 | W17: =L22 -> 0.042157426 | X17: =I22 -> 5195.0135 | Y17: =Q22 -> 0.2164966 | Z17: =M22 -> WMT | AA17: =I22 -> 5195.0135 | AB17: =M22 -> WMT | AC17: =Q22 -> 0.2164966 | AD17: =M22 -> WMT | AE17: =L22 -> 0.042157426
B18: #VALUE! | C18: Semiconductors & Semiconductor Equipment | D18: 416.35 | E18: 228.86 | F18: 95285.861 | G18: 3.79 | H18: 0.016839206 | I18: 90468.075 | K18: =IF((F18-I18)=0,0,I18/(F18-I18)) -> 18.777934 | L18: =F18/SUM(F7:F22) -> 0.45087609 | M18: =INDEX(Ledger[Ticker],MATCH(B18,Ledger[Stock],0)) -> NVDA | N18: =F18-I18 -> 4817.7863 | O18: =N18/D18 -> 11.571481 | P18: =E18/O18 -> 19.777934 | Q18: {=_xlfn.LET(_xlpm.m,Ledger[Stock]=B18,_xlpm.v,_xlfn.VSTACK(_xlfn._xlws.FILTER(IF(Ledger[Transaction Type]="Buy",-1,1)*Ledger[Transaction Amount],_xlpm.m),F18),_xlpm.d,_xlfn.VSTACK(_xlfn._xlws.FILTER(Ledger[Date],_xlpm.m),TODAY()),_xlpm.r,XIRR(_xlfn.SORTBY(_xlpm.v,_xlpm.d),_xlfn._xlws.SORT(_xlpm.d),IF(SUM(_xlpm.v)<0,-0.1,0.1)),IF(ABS(_xlpm.r)<0.0000001,NA(),_xlpm.r))} -> 0.74484886 | R18: =IF(OR(K18<0,Q18<0,L18>0.2),"HIGH",IF(OR(K18<0.5,Q18<0.05,L18>0.15),"MEDIUM","LOW")) -> HIGH | S18: =IF(AND(Q18>0.1,K18>1,P18>1.5,R18="LOW"),"▲ STRONG",IF(OR(K18<0,Q18<0),"▼ REVIEW","▶ HOLD")) -> ▶ HOLD
B19: #VALUE! | C19: Aerospace & Defense | D19: 23.17 | E19: 189.39 | F19: 4388.1663 | G19: 0.39 | H19: 0.0020634921 | I19: 2220.996 | K19: =IF((F19-I19)=0,0,I19/(F19-I19)) -> 1.0248369 | L19: =F19/SUM(F7:F22) -> 0.020764038 | M19: =INDEX(Ledger[Ticker],MATCH(B19,Ledger[Stock],0)) -> 0R2N | N19: =F19-I19 -> 2167.1703 | O19: =N19/D19 -> 93.53346 | P19: =E19/O19 -> 2.0248369 | Q19: {=_xlfn.LET(_xlpm.m,Ledger[Stock]=B19,_xlpm.v,_xlfn.VSTACK(_xlfn._xlws.FILTER(IF(Ledger[Transaction Type]="Buy",-1,1)*Ledger[Transaction Amount],_xlpm.m),F19),_xlpm.d,_xlfn.VSTACK(_xlfn._xlws.FILTER(Ledger[Date],_xlpm.m),TODAY()),_xlpm.r,XIRR(_xlfn.SORTBY(_xlpm.v,_xlpm.d),_xlfn._xlws.SORT(_xlpm.d),IF(SUM(_xlpm.v)<0,-0.1,0.1)),IF(ABS(_xlpm.r)<0.0000001,NA(),_xlpm.r))} -> 0.13563055 | R19: =IF(OR(K19<0,Q19<0,L19>0.2),"HIGH",IF(OR(K19<0.5,Q19<0.05,L19>0.15),"MEDIUM","LOW")) -> LOW | S19: =IF(AND(Q19>0.1,K19>1,P19>1.5,R19="LOW"),"▲ STRONG",IF(OR(K19<0,Q19<0),"▼ REVIEW","▶ HOLD")) -> ▲ STRONG
B20: #VALUE! | C20: Aerospace & Defense | D20: 2.55 | E20: 184.39 | F20: 470.1945 | G20: -13.68 | H20: -0.069066492 | I20: -166.47057 | K20: =IF((F20-I20)=0,0,I20/(F20-I20)) -> -0.26147276 | L20: =F20/SUM(F7:F22) -> 0.0022248784 | M20: =INDEX(Ledger[Ticker],MATCH(B20,Ledger[Stock],0)) -> BA | N20: =F20-I20 -> 636.66507 | O20: =N20/D20 -> 249.67258 | P20: =E20/O20 -> 0.73852724 | Q20: {=_xlfn.LET(_xlpm.m,Ledger[Stock]=B20,_xlpm.v,_xlfn.VSTACK(_xlfn._xlws.FILTER(IF(Ledger[Transaction Type]="Buy",-1,1)*Ledger[Transaction Amount],_xlpm.m),F20),_xlpm.d,_xlfn.VSTACK(_xlfn._xlws.FILTER(Ledger[Date],_xlpm.m),TODAY()),_xlpm.r,XIRR(_xlfn.SORTBY(_xlpm.v,_xlpm.d),_xlfn._xlws.SORT(_xlpm.d),IF(SUM(_xlpm.v)<0,-0.1,0.1)),IF(ABS(_xlpm.r)<0.0000001,NA(),_xlpm.r))} -> -0.13631248 | R20: =IF(OR(K20<0,Q20<0,L20>0.2),"HIGH",IF(OR(K20<0.5,Q20<0.05,L20>0.15),"MEDIUM","LOW")) -> HIGH | S20: =IF(AND(Q20>0.1,K20>1,P20>1.5,R20="LOW"),"▲ STRONG",IF(OR(K20<0,Q20<0),"▼ REVIEW","▶ HOLD")) -> ▼ REVIEW
B21: #VALUE! | C21: Automobiles & Auto Parts | D21: 11.29 | E21: 188.3 | F21: 2125.907 | G21: -2.04 | H21: -0.010717663 | I21: 383.87057 | K21: =IF((F21-I21)=0,0,I21/(F21-I21)) -> 0.22035737 | L21: =F21/SUM(F7:F22) -> 0.010059421 | M21: =INDEX(Ledger[Ticker],MATCH(B21,Ledger[Stock],0)) -> TM | N21: =F21-I21 -> 1742.0364 | O21: =N21/D21 -> 154.29906 | P21: =E21/O21 -> 1.2203574 | Q21: {=_xlfn.LET(_xlpm.m,Ledger[Stock]=B21,_xlpm.v,_xlfn.VSTACK(_xlfn._xlws.FILTER(IF(Ledger[Transaction Type]="Buy",-1,1)*Ledger[Transaction Amount],_xlpm.m),F21),_xlpm.d,_xlfn.VSTACK(_xlfn._xlws.FILTER(Ledger[Date],_xlpm.m),TODAY()),_xlpm.r,XIRR(_xlfn.SORTBY(_xlpm.v,_xlpm.d),_xlfn._xlws.SORT(_xlpm.d),IF(SUM(_xlpm.v)<0,-0.1,0.1)),IF(ABS(_xlpm.r)<0.0000001,NA(),_xlpm.r))} -> 0.051768842 | R21: =IF(OR(K21<0,Q21<0,L21>0.2),"HIGH",IF(OR(K21<0.5,Q21<0.05,L21>0.15),"MEDIUM","LOW")) -> MEDIUM | S21: =IF(AND(Q21>0.1,K21>1,P21>1.5,R21="LOW"),"▲ STRONG",IF(OR(K21<0,Q21<0),"▼ REVIEW","▶ HOLD")) -> ▶ HOLD
B22: #VALUE! | C22: Food & Drug Retailing | D22: 81.94 | E22: 108.73 | F22: 8909.3362 | G22: 0.75 | H22: 0.0069457307 | I22: 5195.0135 | K22: =IF((F22-I22)=0,0,I22/(F22-I22)) -> 1.3986435 | L22: =F22/SUM(F7:F22) -> 0.042157426 | M22: =INDEX(Ledger[Ticker],MATCH(B22,Ledger[Stock],0)) -> WMT | N22: =F22-I22 -> 3714.3227 | O22: =N22/D22 -> 45.329787 | P22: =E22/O22 -> 2.3986435 | Q22: {=_xlfn.LET(_xlpm.m,Ledger[Stock]=B22,_xlpm.v,_xlfn.VSTACK(_xlfn._xlws.FILTER(IF(Ledger[Transaction Type]="Buy",-1,1)*Ledger[Transaction Amount],_xlpm.m),F22),_xlpm.d,_xlfn.VSTACK(_xlfn._xlws.FILTER(Ledger[Date],_xlpm.m),TODAY()),_xlpm.r,XIRR(_xlfn.SORTBY(_xlpm.v,_xlpm.d),_xlfn._xlws.SORT(_xlpm.d),IF(SUM(_xlpm.v)<0,-0.1,0.1)),IF(ABS(_xlpm.r)<0.0000001,NA(),_xlpm.r))} -> 0.2164966 | R22: =IF(OR(K22<0,Q22<0,L22>0.2),"HIGH",IF(OR(K22<0.5,Q22<0.05,L22>0.15),"MEDIUM","LOW")) -> LOW | S22: =IF(AND(Q22>0.1,K22>1,P22>1.5,R22="LOW"),"▲ STRONG",IF(OR(K22<0,Q22<0),"▼ REVIEW","▶ HOLD")) -> ▲ STRONG
B24: COST BASIS | C24: TOP HOLDING | E24: TOP 3 CONC. | G24: AVG RETURN | I24: PROFITABLE | K24: HHI INDEX | M24: ▲ STRONG | N24: ▶ HOLD | O24: ▼ REVIEW | P24: REALISED P&L | Q24: SORTINO RATIO | R24: CALMAR RATIO | S24: PORT. GRADE
B25: =SUM(_xlfn.ANCHORARRAY(F7))-SUM(_xlfn.ANCHORARRAY(I7)) -> 42915.801 | C25: =INDEX(Ledger[Ticker],MATCH(INDEX(_xlfn.ANCHORARRAY(B7),MATCH(MAX(L7:L22),L7:L22,0)),Ledger[Stock],0))&" "&TEXT(MAX(L7:L22),"0.0%") -> NVDA 45.1% | E25: =LARGE(L7:L22,1)+LARGE(L7:L22,2)+LARGE(L7:L22,3) -> 0.67610853 | G25: =AVERAGE(K7:K22) -> 2.7406333 | I25: =COUNTIF(I7:I22,">0")&" / "&COUNTA(I7:I22) -> 15 / 16 | K25: {=SUMPRODUCT((SUMIF(_xlfn.ANCHORARRAY(C7),_xlfn.UNIQUE(_xlfn.ANCHORARRAY(C7)),_xlfn.ANCHORARRAY(F7))/SUM(_xlfn.ANCHORARRAY(F7)))^2)} -> 0.40936259 | M25: =COUNTIF(S7:S22,"*STRONG*") -> 8 | N25: =COUNTIF(S7:S22,"*HOLD*") -> 7 | O25: =COUNTIF(S7:S22,"*REVIEW*") -> 1 | P25: =SUM(Analytics!I10:I25) -> 14943.725 | Q25: ='Risk Analytics'!C19 -> 1.8188661 | R25: ='Risk Analytics'!C20 -> 2.4073308 | S25: =Analytics!H44 -> B+
B28: SECTOR ALLOCATION | G28: REBALANCING ANALYSIS
B29: Industry | C29: Market Value | D29: Weight % | E29: HHI Contrib. | G29: Stock | H29: Current Wt. | I29: Equal Wt. | J29: Deviation | K29: Action
B30: {=_xlfn.UNIQUE(_xlfn.ANCHORARRAY(C7))} -> Semiconductors & Semiconductor Equipment | C30: {=SUMIF(_xlfn.ANCHORARRAY(C7),_xlfn.ANCHORARRAY(B30),_xlfn.ANCHORARRAY(F7))} -> 131600.01 | D30: =C30/SUM(C$30:C$39) -> 0.62270833 | E30: =D30^2 -> 0.38776567 | G30: =M7 -> AMD | H30: =L7 -> 0.17183225 | I30: =1/COUNTA(L$7:L$22) -> 0.0625 | J30: =L7-(1/COUNTA(L$7:L$22)) -> 0.10933225 | K30: =IF(ABS(J30)>0.1,IF(J30>0,"🔻 TRIM","🔺 ADD"),IF(ABS(J30)>0.03,IF(J30>0,"▿ trim","▵ add"),"✔ OK")) -> 🔻 TRIM
B31: Software & IT Services | C31: 22565.789 | D31: =C31/SUM(C$30:C$39) -> 0.10677738 | E31: =D31^2 -> 0.011401409 | G31: =M8 -> GOOG | H31: =L8 -> 0.053377178 | I31: =1/COUNTA(L$7:L$22) -> 0.0625 | J31: =L8-(1/COUNTA(L$7:L$22)) -> -0.009122822 | K31: =IF(ABS(J31)>0.1,IF(J31>0,"🔻 TRIM","🔺 ADD"),IF(ABS(J31)>0.03,IF(J31>0,"▿ trim","▵ add"),"✔ OK")) -> ✔ OK
B32: Diversified Retail | C32: 5161.7655 | D32: =C32/SUM(C$30:C$39) -> 0.024424575 | E32: =D32^2 -> 0.00059655985 | G32: =M9 -> AMZN | H32: =L9 -> 0.024424575 | I32: =1/COUNTA(L$7:L$22) -> 0.0625 | J32: =L9-(1/COUNTA(L$7:L$22)) -> -0.038075425 | K32: =IF(ABS(J32)>0.1,IF(J32>0,"🔻 TRIM","🔺 ADD"),IF(ABS(J32)>0.03,IF(J32>0,"▿ trim","▵ add"),"✔ OK")) -> ▵ add
B33: Computers, Phones & Household Electronics | C33: 9976.032 | D33: =C33/SUM(C$30:C$39) -> 0.047204845 | E33: =D33^2 -> 0.0022282973 | G33: =M10 -> AAPL | H33: =L10 -> 0.047204845 | I33: =1/COUNTA(L$7:L$22) -> 0.0625 | J33: =L10-(1/COUNTA(L$7:L$22)) -> -0.015295155 | K33: =IF(ABS(J33)>0.1,IF(J33>0,"🔻 TRIM","🔺 ADD"),IF(ABS(J33)>0.03,IF(J33>0,"▿ trim","▵ add"),"✔ OK")) -> ✔ OK
B34: Investment Banking & Investment Services | C34: 10720.042 | D34: =C34/SUM(C$30:C$39) -> 0.050725369 | E34: =D34^2 -> 0.0025730631 | G34: =M11 -> BLK | H34: =L11 -> 0.023367944 | I34: =1/COUNTA(L$7:L$22) -> 0.0625 | J34: =L11-(1/COUNTA(L$7:L$22)) -> -0.039132056 | K34: =IF(ABS(J34)>0.1,IF(J34>0,"🔻 TRIM","🔺 ADD"),IF(ABS(J34)>0.03,IF(J34>0,"▿ trim","▵ add"),"✔ OK")) -> ▵ add
B35: Oil & Gas | C35: 3745.6155 | D35: =C35/SUM(C$30:C$39) -> 0.0177236 | E35: =D35^2 -> 0.00031412598 | G35: =M12 -> CVX | H35: =L12 -> 0.0177236 | I35: =1/COUNTA(L$7:L$22) -> 0.0625 | J35: =L12-(1/COUNTA(L$7:L$22)) -> -0.0447764 | K35: =IF(ABS(J35)>0.1,IF(J35>0,"🔻 TRIM","🔺 ADD"),IF(ABS(J35)>0.03,IF(J35>0,"▿ trim","▵ add"),"✔ OK")) -> ▵ add
B36: Automobiles & Auto Parts | C36: 5881.3667 | D36: =C36/SUM(C$30:C$39) -> 0.027829602 | E36: =D36^2 -> 0.00077448675 | G36: =M13 -> C | H36: =L13 -> 0.027357425 | I36: =1/COUNTA(L$7:L$22) -> 0.0625 | J36: =L13-(1/COUNTA(L$7:L$22)) -> -0.035142575 | K36: =IF(ABS(J36)>0.1,IF(J36>0,"🔻 TRIM","🔺 ADD"),IF(ABS(J36)>0.03,IF(J36>0,"▿ trim","▵ add"),"✔ OK")) -> ▵ add
B37: Banking Services | C37: 7916.5968 | D37: =C37/SUM(C$30:C$39) -> 0.037459956 | E37: =D37^2 -> 0.0014032483 | G37: =M14 -> F | H37: =L14 -> 0.010201707 | I37: =1/COUNTA(L$7:L$22) -> 0.0625 | J37: =L14-(1/COUNTA(L$7:L$22)) -> -0.052298293 | K37: =IF(ABS(J37)>0.1,IF(J37>0,"🔻 TRIM","🔺 ADD"),IF(ABS(J37)>0.03,IF(J37>0,"▿ trim","▵ add"),"✔ OK")) -> ▵ add
B38: Aerospace & Defense | C38: 4858.3608 | D38: =C38/SUM(C$30:C$39) -> 0.022988916 | E38: =D38^2 -> 0.00052849028 | G38: =M15 -> HMC | H38: =L15 -> 0.0075684733 | I38: =1/COUNTA(L$7:L$22) -> 0.0625 | J38: =L15-(1/COUNTA(L$7:L$22)) -> -0.054931527 | K38: =IF(ABS(J38)>0.1,IF(J38>0,"🔻 TRIM","🔺 ADD"),IF(ABS(J38)>0.03,IF(J38>0,"▿ trim","▵ add"),"✔ OK")) -> ▵ add
B39: Food & Drug Retailing | C39: 8909.3362 | D39: =C39/SUM(C$30:C$39) -> 0.042157426 | E39: =D39^2 -> 0.0017772486 | G39: =M16 -> JPM | H39: =L16 -> 0.037459956 | I39: =1/COUNTA(L$7:L$22) -> 0.0625 | J39: =L16-(1/COUNTA(L$7:L$22)) -> -0.025040044 | K39: =IF(ABS(J39)>0.1,IF(J39>0,"🔻 TRIM","🔺 ADD"),IF(ABS(J39)>0.03,IF(J39>0,"▿ trim","▵ add"),"✔ OK")) -> ✔ OK
G40: =M17 -> META | H40: =L17 -> 0.053400202 | I40: =1/COUNTA(L$7:L$22) -> 0.0625 | J40: =L17-(1/COUNTA(L$7:L$22)) -> -0.0090997979 | K40: =IF(ABS(J40)>0.1,IF(J40>0,"🔻 TRIM","🔺 ADD"),IF(ABS(J40)>0.03,IF(J40>0,"▿ trim","▵ add"),"✔ OK")) -> ✔ OK
G41: =M18 -> NVDA | H41: =L18 -> 0.45087609 | I41: =1/COUNTA(L$7:L$22) -> 0.0625 | J41: =L18-(1/COUNTA(L$7:L$22)) -> 0.38837609 | K41: =IF(ABS(J41)>0.1,IF(J41>0,"🔻 TRIM","🔺 ADD"),IF(ABS(J41)>0.03,IF(J41>0,"▿ trim","▵ add"),"✔ OK")) -> 🔻 TRIM
G42: =M19 -> 0R2N | H42: =L19 -> 0.020764038 | I42: =1/COUNTA(L$7:L$22) -> 0.0625 | J42: =L19-(1/COUNTA(L$7:L$22)) -> -0.041735962 | K42: =IF(ABS(J42)>0.1,IF(J42>0,"🔻 TRIM","🔺 ADD"),IF(ABS(J42)>0.03,IF(J42>0,"▿ trim","▵ add"),"✔ OK")) -> ▵ add
G43: =M20 -> BA | H43: =L20 -> 0.0022248784 | I43: =1/COUNTA(L$7:L$22) -> 0.0625 | J43: =L20-(1/COUNTA(L$7:L$22)) -> -0.060275122 | K43: =IF(ABS(J43)>0.1,IF(J43>0,"🔻 TRIM","🔺 ADD"),IF(ABS(J43)>0.03,IF(J43>0,"▿ trim","▵ add"),"✔ OK")) -> ▵ add
...

Sheet WL Dashboard
B2: WATCHLIST DASHBOARD
B3: TOTAL MARKET CAP | C3: AVG P/E RATIO | D3: AVG BETA | E3: HIGHEST P/E | F3: LOWEST P/E | G3: TOP GAINER TODAY | H3: TOP LOSER TODAY | I3: STOCKS | J3: INDUSTRIES | K3: MEDIAN P/E
B4: =SUM(Watchlist!J2:INDEX(Watchlist!J:J,COUNTA(Watchlist!J:J))) -> 7311804479772 | C4: =AVERAGE(Watchlist!F2:INDEX(Watchlist!F:F,COUNTA(Watchlist!F:F))) -> 39.14644 | D4: =AVERAGE(Watchlist!E2:INDEX(Watchlist!E:E,COUNTA(Watchlist!E:E))) -> 1.04603 | E4: {=INDEX(Watchlist!B:B,MATCH(MAX(Watchlist!F$2:INDEX(Watchlist!F:F,COUNTA(Watchlist!F:F))),Watchlist!F$2:INDEX(Watchlist!F:F,COUNTA(Watchlist!F:F)),0)+1)&" "&TEXT(MAX(Watchlist!F$2:INDEX(Watchlist!F:F,COUNTA(Watchlist!F:F))),"0.0x")} -> AMD 155.1x | F4: {=INDEX(Watchlist!B:B,MATCH(MIN(Watchlist!F$2:INDEX(Watchlist!F:F,COUNTA(Watchlist!F:F))),Watchlist!F$2:INDEX(Watchlist!F:F,COUNTA(Watchlist!F:F)),0)+1)&" "&TEXT(MIN(Watchlist!F$2:INDEX(Watchlist!F:F,COUNTA(Watchlist!F:F))),"0.0x")} -> BAC 12.8x | G4: {="▲ "&INDEX(Watchlist!B:B,MATCH(MAX(Watchlist!G$2:INDEX(Watchlist!G:G,COUNTA(Watchlist!G:G))),Watchlist!G$2:INDEX(Watchlist!G:G,COUNTA(Watchlist!G:G)),0)+1)} -> ▲ XOM | H4: {="▼ "&INDEX(Watchlist!B:B,MATCH(MIN(Watchlist!G$2:INDEX(Watchlist!G:G,COUNTA(Watchlist!G:G))),Watchlist!G$2:INDEX(Watchlist!G:G,COUNTA(Watchlist!G:G)),0)+1)} -> ▼ AMD | I4: =COUNTA(Watchlist!B2:INDEX(Watchlist!B:B,COUNTA(Watchlist!B:B))) -> 10 | J4: =COUNTA(_xlfn.UNIQUE(Watchlist!K2:INDEX(Watchlist!K:K,COUNTA(Watchlist!K:K)))) -> 9 | K4: =MEDIAN(Watchlist!F2:INDEX(Watchlist!F:F,COUNTA(Watchlist!F:F))) -> 26.31065
B6: WATCHLIST STOCKS · LIVE MARKET DATA · 52-WEEK ANALYSIS
B7: Ticker | C7: Industry | D7: Current Price | E7: Change ($) | F7: P/E Ratio | G7: Beta | H7: Market Cap | I7: 52W High | J7: 52W Low | K7: 52W Range %
B8: =Watchlist!B2 -> AMD | C8: =Watchlist!K2 -> Semiconductors & Semiconductor Equipment | D8: =(Watchlist!H2+Watchlist!I2)/2 -> 612.91 | E8: =Watchlist!G2 -> -22.76 | F8: =Watchlist!F2 -> 155.1433 | G8: =Watchlist!E2 -> 2.4824 | H8: =Watchlist!J2 -> 992332578250 | I8: =Watchlist!C2 -> 639 | J8: =Watchlist!D2 -> 159.33 | K8: =((Watchlist!H2+Watchlist!I2)/2-Watchlist!D2)/(Watchlist!C2-Watchlist!D2) -> 0.94560844 | M8: Ticker | N8: 52W Range %
B9: =Watchlist!B3 -> MSFT | C9: =Watchlist!K3 -> Software & IT Services | D9: =(Watchlist!H3+Watchlist!I3)/2 -> 507.775 | E9: =Watchlist!G3 -> -6.95 | F9: =Watchlist!F3 -> 28.3741 | G9: =Watchlist!E3 -> 1.1008 | H9: =Watchlist!J3 -> 3781236024900 | I9: =Watchlist!C3 -> 553.72 | J9: =Watchlist!D3 -> 349.2 | K9: =((Watchlist!H3+Watchlist!I3)/2-Watchlist!D3)/(Watchlist!C3-Watchlist!D3) -> 0.77535204 | M9: =B8 -> AMD | N9: =K8 -> 0.94560844
B10: =Watchlist!B4 -> BABA | C10: =Watchlist!K4 -> Software & IT Services | D10: =(Watchlist!H4+Watchlist!I4)/2 -> 109.44 | E10: =Watchlist!G4 -> -0.98 | F10: =Watchlist!F4 -> 24.2472 | G10: =Watchlist!E4 -> 0.4616 | H10: =Watchlist!J4 -> 270336466240 | I10: =Watchlist!C4 -> 192.67 | J10: =Watchlist!D4 -> 91.99 | K10: =((Watchlist!H4+Watchlist!I4)/2-Watchlist!D4)/(Watchlist!C4-Watchlist!D4) -> 0.17332141 | M10: =B9 -> MSFT | N10: =K9 -> 0.77535204
B11: =Watchlist!B5 -> DELL | C11: =Watchlist!K5 -> Computers, Phones & Household Electronics | D11: =(Watchlist!H5+Watchlist!I5)/2 -> 546.25 | E11: =Watchlist!G5 -> -19.46 | F11: =Watchlist!F5 -> 31.5313 | G11: =Watchlist!E5 -> 1.3675 | H11: =Watchlist!J5 -> 345519695560 | I11: =Watchlist!C5 -> 595.51 | J11: =Watchlist!D5 -> 110.22 | K11: =((Watchlist!H5+Watchlist!I5)/2-Watchlist!D5)/(Watchlist!C5-Watchlist!D5) -> 0.89849368 | M11: =B10 -> BABA | N11: =K10 -> 0.17332141
B12: =Watchlist!B6 -> GS | C12: =Watchlist!K6 -> Investment Banking & Investment Services | D12: =(Watchlist!H6+Watchlist!I6)/2 -> 923.25 | E12: =Watchlist!G6 -> -19.17 | F12: =Watchlist!F6 -> 14.1387 | G12: =Watchlist!E6 -> 1.2712 | H12: =Watchlist!J6 -> 266794530392 | I12: =Watchlist!C6 -> 1153.99 | J12: =Watchlist!D6 -> 740.01 | K12: =((Watchlist!H6+Watchlist!I6)/2-Watchlist!D6)/(Watchlist!C6-Watchlist!D6) -> 0.44263008 | M12: =B11 -> DELL | N12: =K11 -> 0.89849368
B13: =Watchlist!B7 -> XOM | C13: =Watchlist!K7 -> Oil & Gas | D13: =(Watchlist!H7+Watchlist!I7)/2 -> 162.295 | E13: =Watchlist!G7 -> 1.93 | F13: =Watchlist!F7 -> 20.9585 | G13: =Watchlist!E7 -> 0.2089 | H13: =Watchlist!J7 -> 668267938240 | I13: =Watchlist!C7 -> 176.41 | J13: =Watchlist!D7 -> 110.385 | K13: =((Watchlist!H7+Watchlist!I7)/2-Watchlist!D7)/(Watchlist!C7-Watchlist!D7) -> 0.78621734 | M13: =B12 -> GS | N13: =K12 -> 0.44263008
B14: =Watchlist!B8 -> GM | C14: =Watchlist!K8 -> Automobiles & Auto Parts | D14: =(Watchlist!H8+Watchlist!I8)/2 -> 81.56 | E14: =Watchlist!G8 -> -1.99 | F14: =Watchlist!F8 -> 40.6735 | G14: =Watchlist!E8 -> 1.3933 | H14: =Watchlist!J8 -> 70757688960 | I14: =Watchlist!C8 -> 91.85 | J14: =Watchlist!D8 -> 54.33 | K14: =((Watchlist!H8+Watchlist!I8)/2-Watchlist!D8)/(Watchlist!C8-Watchlist!D8) -> 0.72574627 | M14: =B13 -> XOM | N14: =K13 -> 0.78621734
B15: =Watchlist!B9 -> BAC | C15: =Watchlist!K9 -> Banking Services | D15: =(Watchlist!H9+Watchlist!I9)/2 -> 56.0175 | E15: =Watchlist!G9 -> -1.23 | F15: =Watchlist!F9 -> 12.8487 | G15: =Watchlist!E9 -> 1.209 | H15: =Watchlist!J9 -> 387887787030 | I15: =Watchlist!C9 -> 65.225 | J15: =Watchlist!D9 -> 46.115 | K15: =((Watchlist!H9+Watchlist!I9)/2-Watchlist!D9)/(Watchlist!C9-Watchlist!D9) -> 0.5181842 | M15: =B14 -> GM | N15: =K14 -> 0.72574627
B16: =Watchlist!B10 -> LMT | C16: =Watchlist!K10 -> Aerospace & Defense | D16: =(Watchlist!H10+Watchlist!I10)/2 -> 520.185 | E16: =Watchlist!G10 -> -1.46 | F16: =Watchlist!F10 -> 19.091 | G16: =Watchlist!E10 -> 0.0903 | H16: =Watchlist!J10 -> 119572713480 | I16: =Watchlist!C10 -> 692 | J16: =Watchlist!D10 -> 437.25 | K16: =((Watchlist!H10+Watchlist!I10)/2-Watchlist!D10)/(Watchlist!C10-Watchlist!D10) -> 0.32555447 | M16: =B15 -> BAC | N16: =K15 -> 0.5181842
B17: =Watchlist!B11 -> COST | C17: =Watchlist!K11 -> Diversified Retail | D17: =(Watchlist!H11+Watchlist!I11)/2 -> 922.045 | E17: =Watchlist!G11 -> 0.155 | F17: =Watchlist!F11 -> 44.4581 | G17: =Watchlist!E11 -> 0.8753 | H17: =Watchlist!J11 -> 409099056720 | I17: =Watchlist!C11 -> 1096.5 | J17: =Watchlist!D11 -> 844.06 | K17: =((Watchlist!H11+Watchlist!I11)/2-Watchlist!D11)/(Watchlist!C11-Watchlist!D11) -> 0.30892489 | M17: =B16 -> LMT | N17: =K16 -> 0.32555447
M18: =B17 -> COST | N18: =K17 -> 0.30892489
B19: VISUALIZATIONS
B51: 52-WEEK RANGE ANALYSIS
B53: Industry | C53: Market Cap
B54: {=_xlfn.UNIQUE(C8:C17)} -> Semiconductors & Semiconductor Equipment | C54: {=SUMIF(C8:C17,_xlfn.ANCHORARRAY(B54),H8:H17)} -> 992332578250
B55: Software & IT Services | C55: 4051572491140
B56: Computers, Phones & Household Electronics | C56: 345519695560
B57: Investment Banking & Investment Services | C57: 266794530392
B58: Oil & Gas | C58: 668267938240
B59: Automobiles & Auto Parts | C59: 70757688960
B60: Banking Services | C60: 387887787030
B61: Aerospace & Defense | C61: 119572713480
B62: Diversified Retail | C62: 409099056720
B64: COMPARATIVE VALUATION & MOMENTUM ANALYTICS
B65: Multi-Factor Scoring Model — Ranks Watchlist Stocks by Value, Momentum & Risk
B66: Ticker | C66: P/E | D66: P/E Rank | E66: Beta | F66: Risk Rank | G66: 52W Range % | H66: Momentum | I66: Value Score | J66: Composite | K66: Signal
B67: =B8 -> AMD | C67: =F8 -> 155.1433 | D67: =RANK(F8,F$8:F$17,1) -> 10 | E67: =G8 -> 2.4824 | F67: =RANK(G8,G$8:G$17,1) -> 10 | G67: =K8 -> 0.94560844 | H67: =IF(K8>0.7,"▲ STRONG",IF(K8>0.3,"▶ NEUTRAL","▼ WEAK")) -> ▲ STRONG | I67: =(RANK(F8,F$8:F$17,1)*0.4)+(RANK(G8,G$8:G$17,1)*0.3)+(RANK(K8,K$8:K$17,0)*0.3) -> 7.3 | J67: =RANK(I67,I$67:I$76,1) -> 8 | K67: =IF(J67<=3,"⭐ BUY",IF(J67<=7,"🔍 WATCH","⚠️ AVOID")) -> ⚠️ AVOID
B68: =B9 -> MSFT | C68: =F9 -> 28.3741 | D68: =RANK(F9,F$8:F$17,1) -> 6 | E68: =G9 -> 1.1008 | F68: =RANK(G9,G$8:G$17,1) -> 5 | G68: =K9 -> 0.77535204 | H68: =IF(K9>0.7,"▲ STRONG",IF(K9>0.3,"▶ NEUTRAL","▼ WEAK")) -> ▲ STRONG | I68: =(RANK(F9,F$8:F$17,1)*0.4)+(RANK(G9,G$8:G$17,1)*0.3)+(RANK(K9,K$8:K$17,0)*0.3) -> 5.1 | J68: =RANK(I68,I$67:I$76,1) -> 5 | K68: =IF(J68<=3,"⭐ BUY",IF(J68<=7,"🔍 WATCH","⚠️ AVOID")) -> 🔍 WATCH
B69: =B10 -> BABA | C69: =F10 -> 24.2472 | D69: =RANK(F10,F$8:F$17,1) -> 5 | E69: =G10 -> 0.4616 | F69: =RANK(G10,G$8:G$17,1) -> 3 | G69: =K10 -> 0.17332141 | H69: =IF(K10>0.7,"▲ STRONG",IF(K10>0.3,"▶ NEUTRAL","▼ WEAK")) -> ▼ WEAK | I69: =(RANK(F10,F$8:F$17,1)*0.4)+(RANK(G10,G$8:G$17,1)*0.3)+(RANK(K10,K$8:K$17,0)*0.3) -> 5.9 | J69: =RANK(I69,I$67:I$76,1) -> 7 | K69: =IF(J69<=3,"⭐ BUY",IF(J69<=7,"🔍 WATCH","⚠️ AVOID")) -> 🔍 WATCH
B70: =B11 -> DELL | C70: =F11 -> 31.5313 | D70: =RANK(F11,F$8:F$17,1) -> 7 | E70: =G11 -> 1.3675 | F70: =RANK(G11,G$8:G$17,1) -> 8 | G70: =K11 -> 0.89849368 | H70: =IF(K11>0.7,"▲ STRONG",IF(K11>0.3,"▶ NEUTRAL","▼ WEAK")) -> ▲ STRONG | I70: =(RANK(F11,F$8:F$17,1)*0.4)+(RANK(G11,G$8:G$17,1)*0.3)+(RANK(K11,K$8:K$17,0)*0.3) -> 5.8 | J70: =RANK(I70,I$67:I$76,1) -> 6 | K70: =IF(J70<=3,"⭐ BUY",IF(J70<=7,"🔍 WATCH","⚠️ AVOID")) -> 🔍 WATCH
B71: =B12 -> GS | C71: =F12 -> 14.1387 | D71: =RANK(F12,F$8:F$17,1) -> 2 | E71: =G12 -> 1.2712 | F71: =RANK(G12,G$8:G$17,1) -> 7 | G71: =K12 -> 0.44263008 | H71: =IF(K12>0.7,"▲ STRONG",IF(K12>0.3,"▶ NEUTRAL","▼ WEAK")) -> ▶ NEUTRAL | I71: =(RANK(F12,F$8:F$17,1)*0.4)+(RANK(G12,G$8:G$17,1)*0.3)+(RANK(K12,K$8:K$17,0)*0.3) -> 5 | J71: =RANK(I71,I$67:I$76,1) -> 4 | K71: =IF(J71<=3,"⭐ BUY",IF(J71<=7,"🔍 WATCH","⚠️ AVOID")) -> 🔍 WATCH
B72: =B13 -> XOM | C72: =F13 -> 20.9585 | D72: =RANK(F13,F$8:F$17,1) -> 4 | E72: =G13 -> 0.2089 | F72: =RANK(G13,G$8:G$17,1) -> 2 | G72: =K13 -> 0.78621734 | H72: =IF(K13>0.7,"▲ STRONG",IF(K13>0.3,"▶ NEUTRAL","▼ WEAK")) -> ▲ STRONG | I72: =(RANK(F13,F$8:F$17,1)*0.4)+(RANK(G13,G$8:G$17,1)*0.3)+(RANK(K13,K$8:K$17,0)*0.3) -> 3.1 | J72: =RANK(I72,I$67:I$76,1) -> 1 | K72: =IF(J72<=3,"⭐ BUY",IF(J72<=7,"🔍 WATCH","⚠️ AVOID")) -> ⭐ BUY
B73: =B14 -> GM | C73: =F14 -> 40.6735 | D73: =RANK(F14,F$8:F$17,1) -> 8 | E73: =G14 -> 1.3933 | F73: =RANK(G14,G$8:G$17,1) -> 9 | G73: =K14 -> 0.72574627 | H73: =IF(K14>0.7,"▲ STRONG",IF(K14>0.3,"▶ NEUTRAL","▼ WEAK")) -> ▲ STRONG | I73: =(RANK(F14,F$8:F$17,1)*0.4)+(RANK(G14,G$8:G$17,1)*0.3)+(RANK(K14,K$8:K$17,0)*0.3) -> 7.4 | J73: =RANK(I73,I$67:I$76,1) -> 9 | K73: =IF(J73<=3,"⭐ BUY",IF(J73<=7,"🔍 WATCH","⚠️ AVOID")) -> ⚠️ AVOID
B74: =B15 -> BAC | C74: =F15 -> 12.8487 | D74: =RANK(F15,F$8:F$17,1) -> 1 | E74: =G15 -> 1.209 | F74: =RANK(G15,G$8:G$17,1) -> 6 | G74: =K15 -> 0.5181842 | H74: =IF(K15>0.7,"▲ STRONG",IF(K15>0.3,"▶ NEUTRAL","▼ WEAK")) -> ▶ NEUTRAL | I74: =(RANK(F15,F$8:F$17,1)*0.4)+(RANK(G15,G$8:G$17,1)*0.3)+(RANK(K15,K$8:K$17,0)*0.3) -> 4 | J74: =RANK(I74,I$67:I$76,1) -> 3 | K74: =IF(J74<=3,"⭐ BUY",IF(J74<=7,"🔍 WATCH","⚠️ AVOID")) -> ⭐ BUY
B75: =B16 -> LMT | C75: =F16 -> 19.091 | D75: =RANK(F16,F$8:F$17,1) -> 3 | E75: =G16 -> 0.0903 | F75: =RANK(G16,G$8:G$17,1) -> 1 | G75: =K16 -> 0.32555447 | H75: =IF(K16>0.7,"▲ STRONG",IF(K16>0.3,"▶ NEUTRAL","▼ WEAK")) -> ▶ NEUTRAL | I75: =(RANK(F16,F$8:F$17,1)*0.4)+(RANK(G16,G$8:G$17,1)*0.3)+(RANK(K16,K$8:K$17,0)*0.3) -> 3.9 | J75: =RANK(I75,I$67:I$76,1) -> 2 | K75: =IF(J75<=3,"⭐ BUY",IF(J75<=7,"🔍 WATCH","⚠️ AVOID")) -> ⭐ BUY
...

Sheet Analytics
A1: PORTFOLIO ANALYTICS
A2: Advanced Financial Metrics & Risk Analysis
A4: KEY PORTFOLIO METRICS
A5: Total Cost Basis | B5: Total Market Value | C5: Unrealised P&L | D5: Total Return % (incl. realised) | E5: Ann. Return (IRR) | F5: # Holdings | G5: Best Performer | H5: Worst Performer
A6: =SUM(Dashboard!F7:F22)-SUM(Dashboard!I7:I22) -> 42915.801 | B6: =SUM(Dashboard!F7:F22) -> 211334.92 | C6: =SUM(Dashboard!I7:I22) -> 168419.12 | D6: =Dashboard!F3 -> 2.291699 | E6: =Dashboard!G3 -> 0.32227901 | F6: =COUNTA(Dashboard!M7:M22) -> 16 | G6: =INDEX(Dashboard!M7:M22,MATCH(MAX(Dashboard!I7:I22),Dashboard!I7:I22,0)) -> NVDA | H6: =INDEX(Dashboard!M7:M22,MATCH(MIN(Dashboard!I7:I22),Dashboard!I7:I22,0)) -> BA
A8: INDIVIDUAL STOCK ANALYSIS
A9: Stock | B9: Cost Basis | C9: Market Value | D9: Gain/(Loss) | E9: Return % | F9: Weight % | G9: Avg Buy Price | H9: Ann. Return (IRR) | I9: Realised P&L
A10: =Dashboard!M7 -> AMD | B10: =Dashboard!F7-Dashboard!I7 -> 3207.287 | C10: =Dashboard!F7 -> 36314.154 | D10: =Dashboard!I7 -> 33106.867 | E10: =Dashboard!K7 -> 10.32239 | F10: =Dashboard!L7 -> 0.17183225 | G10: =Dashboard!O7 -> 53.68743 | H10: =Dashboard!Q7 -> 0.55674189 | I10: =SUMIFS(Ledger[Transaction Amount],Ledger[Stock],Dashboard!B7,Ledger[Transaction Type],"Sell")-SUMIFS(Ledger[Units],Ledger[Stock],Dashboard!B7,Ledger[Transaction Type],"Sell")*SUMIFS(Ledger[Transaction Amount],Ledger[Stock],Dashboard!B7,Ledger[Transaction Type],"Buy")/SUMIFS(Ledger[Units],Ledger[Stock],Dashboard!B7,Ledger[Transaction Type],"Buy") -> 1641.4131
A11: =Dashboard!M8 -> GOOG | B11: =Dashboard!F8-Dashboard!I8 -> 3138.4985 | C11: =Dashboard!F8 -> 11280.462 | D11: =Dashboard!I8 -> 8141.9631 | E11: =Dashboard!K8 -> 2.5942224 | F11: =Dashboard!L8 -> 0.053377178 | G11: =Dashboard!O8 -> 94.362552 | H11: =Dashboard!Q8 -> 0.30156799 | I11: =SUMIFS(Ledger[Transaction Amount],Ledger[Stock],Dashboard!B8,Ledger[Transaction Type],"Sell")-SUMIFS(Ledger[Units],Ledger[Stock],Dashboard!B8,Ledger[Transaction Type],"Sell")*SUMIFS(Ledger[Transaction Amount],Ledger[Stock],Dashboard!B8,Ledger[Transaction Type],"Buy")/SUMIFS(Ledger[Units],Ledger[Stock],Dashboard!B8,Ledger[Transaction Type],"Buy") -> 1473.6352
A12: =Dashboard!M9 -> AMZN | B12: =Dashboard!F9-Dashboard!I9 -> 2475.8154 | C12: =Dashboard!F9 -> 5161.7655 | D12: =Dashboard!I9 -> 2685.9501 | E12: =Dashboard!K9 -> 1.0848749 | F12: =Dashboard!L9 -> 0.024424575 | G12: =Dashboard!O9 -> 118.06464 | H12: =Dashboard!Q9 -> 0.19556205 | I12: =SUMIFS(Ledger[Transaction Amount],Ledger[Stock],Dashboard!B9,Ledger[Transaction Type],"Sell")-SUMIFS(Ledger[Units],Ledger[Stock],Dashboard!B9,Ledger[Transaction Type],"Sell")*SUMIFS(Ledger[Transaction Amount],Ledger[Stock],Dashboard!B9,Ledger[Transaction Type],"Buy")/SUMIFS(Ledger[Units],Ledger[Stock],Dashboard!B9,Ledger[Transaction Type],"Buy") -> 1104.8408
A13: =Dashboard!M10 -> AAPL | B13: =Dashboard!F10-Dashboard!I10 -> 3127.4363 | C13: =Dashboard!F10 -> 9976.032 | D13: =Dashboard!I10 -> 6848.5957 | E13: =Dashboard!K10 -> 2.1898434 | F13: =Dashboard!L10 -> 0.047204845 | G13: =Dashboard!O10 -> 106.08671 | H13: =Dashboard!Q10 -> 0.28999216 | I13: =SUMIFS(Ledger[Transaction Amount],Ledger[Stock],Dashboard!B10,Ledger[Transaction Type],"Sell")-SUMIFS(Ledger[Units],Ledger[Stock],Dashboard!B10,Ledger[Transaction Type],"Sell")*SUMIFS(Ledger[Transaction Amount],Ledger[Stock],Dashboard!B10,Ledger[Transaction Type],"Buy")/SUMIFS(Ledger[Units],Ledger[Stock],Dashboard!B10,Ledger[Transaction Type],"Buy") -> 1563.2595
A14: =Dashboard!M11 -> BLK | B14: =Dashboard!F11-Dashboard!I11 -> 3000.2546 | C14: =Dashboard!F11 -> 4938.4625 | D14: =Dashboard!I11 -> 1938.2079 | E14: =Dashboard!K11 -> 0.64601445 | F14: =Dashboard!L11 -> 0.023367944 | G14: =Dashboard!O11 -> 650.81446 | H14: =Dashboard!Q11 -> 0.13977041 | I14: =SUMIFS(Ledger[Transaction Amount],Ledger[Stock],Dashboard!B11,Ledger[Transaction Type],"Sell")-SUMIFS(Ledger[Units],Ledger[Stock],Dashboard!B11,Ledger[Transaction Type],"Sell")*SUMIFS(Ledger[Transaction Amount],Ledger[Stock],Dashboard!B11,Ledger[Transaction Type],"Buy")/SUMIFS(Ledger[Units],Ledger[Stock],Dashboard!B11,Ledger[Transaction Type],"Buy") -> 1163.6182
A15: =Dashboard!M12 -> CVX | B15: =Dashboard!F12-Dashboard!I12 -> 2349.1404 | C15: =Dashboard!F12 -> 3745.6155 | D15: =Dashboard!I12 -> 1396.4751 | E15: =Dashboard!K12 -> 0.59446216 | F15: =Dashboard!L12 -> 0.0177236 | G15: =Dashboard!O12 -> 129.42922 | H15: =Dashboard!Q12 -> 0.077858725 | I15: =SUMIFS(Ledger[Transaction Amount],Ledger[Stock],Dashboard!B12,Ledger[Transaction Type],"Sell")-SUMIFS(Ledger[Units],Ledger[Stock],Dashboard!B12,Ledger[Transaction Type],"Sell")*SUMIFS(Ledger[Transaction Amount],Ledger[Stock],Dashboard!B12,Ledger[Transaction Type],"Buy")/SUMIFS(Ledger[Units],Ledger[Stock],Dashboard!B12,Ledger[Transaction Type],"Buy") -> 256.13621
A16: =Dashboard!M13 -> C | B16: =Dashboard!F13-Dashboard!I13 -> 2406.1481 | C16: =Dashboard!F13 -> 5781.5793 | D16: =Dashboard!I13 -> 3375.4312 | E16: =Dashboard!K13 -> 1.402836 | F16: =Dashboard!L13 -> 0.027357425 | G16: =Dashboard!O13 -> 54.647925 | H16: =Dashboard!Q13 -> 0.17262424 | I16: =SUMIFS(Ledger[Transaction Amount],Ledger[Stock],Dashboard!B13,Ledger[Transaction Type],"Sell")-SUMIFS(Ledger[Units],Ledger[Stock],Dashboard!B13,Ledger[Transaction Type],"Sell")*SUMIFS(Ledger[Transaction Amount],Ledger[Stock],Dashboard!B13,Ledger[Transaction Type],"Buy")/SUMIFS(Ledger[Units],Ledger[Stock],Dashboard!B13,Ledger[Transaction Type],"Buy") -> 646.95522
A17: =Dashboard!M14 -> F | B17: =Dashboard!F14-Dashboard!I14 -> 1819.1895 | C17: =Dashboard!F14 -> 2155.977 | D17: =Dashboard!I14 -> 336.78746 | E17: =Dashboard!K14 -> 0.1851305 | F17: =Dashboard!L14 -> 0.010201707 | G17: =Dashboard!O14 -> 10.446107 | H17: =Dashboard!Q14 -> 0.032022062 | I17: =SUMIFS(Ledger[Transaction Amount],Ledger[Stock],Dashboard!B14,Ledger[Transaction Type],"Sell")-SUMIFS(Ledger[Units],Ledger[Stock],Dashboard!B14,Ledger[Transaction Type],"Sell")*SUMIFS(Ledger[Transaction Amount],Ledger[Stock],Dashboard!B14,Ledger[Transaction Type],"Buy")/SUMIFS(Ledger[Units],Ledger[Stock],Dashboard!B14,Ledger[Transaction Type],"Buy") -> 142.88134
A18: =Dashboard!M15 -> HMC | B18: =Dashboard!F15-Dashboard!I15 -> 1380.415 | C18: =Dashboard!F15 -> 1599.4827 | D18: =Dashboard!I15 -> 219.06771 | E18: =Dashboard!K15 -> 0.15869699 | F18: =Dashboard!L15 -> 0.0075684733 | G18: =Dashboard!O15 -> 28.040118 | H18: =Dashboard!Q15 -> 0.0072583467 | I18: =SUMIFS(Ledger[Transaction Amount],Ledger[Stock],Dashboard!B15,Ledger[Transaction Type],"Sell")-SUMIFS(Ledger[Units],Ledger[Stock],Dashboard!B15,Ledger[Transaction Type],"Sell")*SUMIFS(Ledger[Transaction Amount],Ledger[Stock],Dashboard!B15,Ledger[Transaction Type],"Buy")/SUMIFS(Ledger[Units],Ledger[Stock],Dashboard!B15,Ledger[Transaction Type],"Buy") -> -127.66571
A19: =Dashboard!M16 -> JPM | B19: =Dashboard!F16-Dashboard!I16 -> 3344.5687 | C19: =Dashboard!F16 -> 7916.5968 | D19: =Dashboard!I16 -> 4572.0281 | E19: =Dashboard!K16 -> 1.3670008 | F19: =Dashboard!L16 -> 0.037459956 | G19: =Dashboard!O16 -> 142.20105 | H19: =Dashboard!Q16 -> 0.20443895 | I19: =SUMIFS(Ledger[Transaction Amount],Ledger[Stock],Dashboard!B16,Ledger[Transaction Type],"Sell")-SUMIFS(Ledger[Units],Ledger[Stock],Dashboard!B16,Ledger[Transaction Type],"Sell")*SUMIFS(Ledger[Transaction Amount],Ledger[Stock],Dashboard!B16,Ledger[Transaction Type],"Buy")/SUMIFS(Ledger[Units],Ledger[Stock],Dashboard!B16,Ledger[Transaction Type],"Buy") -> 1348.4299
A20: =Dashboard!M17 -> META | B20: =Dashboard!F17-Dashboard!I17 -> 3589.0667 | C20: =Dashboard!F17 -> 11285.327 | D20: =Dashboard!I17 -> 7696.2607 | E20: =Dashboard!K17 -> 2.1443626 | F20: =Dashboard!L17 -> 0.053400202 | G20: =Dashboard!O17 -> 227.58825 | H20: =Dashboard!Q17 -> 0.29073516 | I20: =SUMIFS(Ledger[Transaction Amount],Ledger[Stock],Dashboard!B17,Ledger[Transaction Type],"Sell")-SUMIFS(Ledger[Units],Ledger[Stock],Dashboard!B17,Ledger[Transaction Type],"Sell")*SUMIFS(Ledger[Transaction Amount],Ledger[Stock],Dashboard!B17,Ledger[Transaction Type],"Buy")/SUMIFS(Ledger[Units],Ledger[Stock],Dashboard!B17,Ledger[Transaction Type],"Buy") -> 1824.1765
